Workbook

Sheet Monthly_Cohort_&_Matrix
A1: Reg. Month | B1: Txn. Month-->> | C1: 44652 | D1: 44682 | E1: 44713 | F1: 44743 | G1: 44774 | H1: 44805 | I1: 44835 | J1: 44866 | K1: 44896 | L1: 44927 | M1: 44958 | N1: 44986
A2: 44652 | B2: Revenue | C2: 3470489 | D2: 4531845.7 | E2: 2016024.7 | F2: 1479962.3 | G2: 1504660.4 | H2: 1611245.6 | I2: 1522136.7 | J2: 1431240.4 | K2: 1447305.2 | L2: 1569349.3 | M2: 1157821 | N2: 1613196.9
B3: Users | C3: 11871 | D3: 1404 | E3: 643 | F3: 525 | G3: 341 | H3: 329 | I3: 328 | J3: 242 | K3: 228 | L3: 220 | M3: 179 | N3: 164
A4: 44682 | B4: Revenue | D4: 5119928.2 | E4: 3251729.4 | F4: 2104764.6 | G4: 1837881.9 | H4: 1139201.3 | I4: 642896.15 | J4: 748966.78 | K4: 1110431.3 | L4: 1033822.6 | M4: 946760.52 | N4: 850348.78
B5: Users | D5: 15998 | E5: 1924 | F5: 916 | G5: 613 | H5: 484 | I5: 475 | J5: 358 | K5: 336 | L5: 313 | M5: 304 | N5: 273
A6: 44713 | B6: Revenue | E6: 3815355.3 | F6: 2577614.2 | G6: 1433445.4 | H6: 1390421.2 | I6: 1348763.1 | J6: 840880.32 | K6: 749196.5 | L6: 663578.6 | M6: 946472.02 | N6: 1186950.9
B7: Users | E7: 19147 | F7: 2181 | G7: 693 | H7: 590 | I7: 507 | J7: 333 | K7: 303 | L7: 254 | M7: 264 | N7: 218
A8: 44743 | B8: Revenue | F8: 4547888.8 | G8: 4166630.6 | H8: 2402552.6 | I8: 1811911.9 | J8: 2653527.7 | K8: 3125232.7 | L8: 2436043.4 | M8: 1559146.1 | N8: 2922084.2
B9: Users | F9: 19360 | G9: 1688 | H9: 831 | I9: 632 | J9: 405 | K9: 357 | L9: 325 | M9: 286 | N9: 243
A10: 44774 | B10: Revenue | G10: 2906573.5 | H10: 1774037.2 | I10: 1403062.7 | J10: 1113653.4 | K10: 1237597.1 | L10: 1538336.2 | M10: 705618.63 | N10: 926147.72
B11: Users | G11: 18585 | H11: 1496 | I11: 726 | J11: 387 | K11: 366 | L11: 287 | M11: 237 | N11: 199
A12: 44805 | B12: Revenue | H12: 2178295.9 | I12: 1319452.6 | J12: 937420.57 | K12: 779976.65 | L12: 1073896 | M12: 519091.13 | N12: 416146.64
B13: Users | H13: 13772 | I13: 1098 | J13: 451 | K13: 336 | L13: 265 | M13: 211 | N13: 172
A14: 44835 | B14: Revenue | I14: 2894310.4 | J14: 2422647.6 | K14: 1103806.6 | L14: 825014.41 | M14: 729020.05 | N14: 1049514.4
B15: Users | I15: 10553 | J15: 952 | K15: 449 | L15: 234 | M15: 185 | N15: 147
A16: 44866 | B16: Revenue | J16: 3252521.6 | K16: 2952210.7 | L16: 1582011.8 | M16: 1297248.4 | N16: 1838872.5
B17: Users | J17: 12935 | K17: 1222 | L17: 415 | M17: 273 | N17: 226
A18: 44896 | B18: Revenue | K18: 2753173.2 | L18: 4530061.7 | M18: 3856710.7 | N18: 3746109.3
B19: Users | K19: 10997 | L19: 860 | M19: 373 | N19: 276
A20: 44927 | B20: Revenue | L20: 3024628.9 | M20: 3455629.5 | N20: 2403373.9
B21: Users | L21: 11697 | M21: 996 | N21: 454
A22: 44958 | B22: Revenue | M22: 3526821.4 | N22: 5357501.1
B23: Users | M23: 11724 | N23: 855
A24: 44986 | B24: Revenue | N24: 2727451.8
B25: Users | N25: 14383
A27: Total | B27: Revenue | C27: =SUMIF($B2:$B25,"Revenue",C2:C25) -> 3470489 | D27: =SUMIF($B2:$B25,"Revenue",D2:D25) -> 9651773.8 | E27: =SUMIF($B2:$B25,"Revenue",E2:E25) -> 9083109.4 | F27: =SUMIF($B2:$B25,"Revenue",F2:F25) -> 10710230 | G27: =SUMIF($B2:$B25,"Revenue",G2:G25) -> 11849192 | H27: =SUMIF($B2:$B25,"Revenue",H2:H25) -> 10495754 | I27: =SUMIF($B2:$B25,"Revenue",I2:I25) -> 10942534 | J27: =SUMIF($B2:$B25,"Revenue",J2:J25) -> 13400858 | ... N27: =SUMIF($B2:$B25,"Revenue",N2:N25) -> 25037698
A28: Total | B28: Users | C28: =SUMIF($B2:$B25,"Users",C2:C25) -> 11871 | D28: =SUMIF($B2:$B25,"Users",D2:D25) -> 17402 | E28: =SUMIF($B2:$B25,"Users",E2:E25) -> 21714 | F28: =SUMIF($B2:$B25,"Users",F2:F25) -> 22982 | G28: =SUMIF($B2:$B25,"Users",G2:G25) -> 21920 | H28: =SUMIF($B2:$B25,"Users",H2:H25) -> 17502 | I28: =SUMIF($B2:$B25,"Users",I2:I25) -> 14319 | J28: =SUMIF($B2:$B25,"Users",J2:J25) -> 16063 | ... N28: =SUMIF($B2:$B25,"Users",N2:N25) -> 17610
A30: New | B30: Users | C30: =OFFSET($C$3,(COLUMN()-COLUMN($C$30))*2,(COLUMN()-COLUMN($C$30))) -> 11871 | D30: =OFFSET($C$3,(COLUMN()-COLUMN($C$30))*2,(COLUMN()-COLUMN($C$30))) -> 15998 | E30: =OFFSET($C$3,(COLUMN()-COLUMN($C$30))*2,(COLUMN()-COLUMN($C$30))) -> 19147 | F30: =OFFSET($C$3,(COLUMN()-COLUMN($C$30))*2,(COLUMN()-COLUMN($C$30))) -> 19360 | G30: =OFFSET($C$3,(COLUMN()-COLUMN($C$30))*2,(COLUMN()-COLUMN($C$30))) -> 18585 | H30: =OFFSET($C$3,(COLUMN()-COLUMN($C$30))*2,(COLUMN()-COLUMN($C$30))) -> 13772 | I30: =OFFSET($C$3,(COLUMN()-COLUMN($C$30))*2,(COLUMN()-COLUMN($C$30))) -> 10553 | J30: =OFFSET($C$3,(COLUMN()-COLUMN($C$30))*2,(COLUMN()-COLUMN($C$30))) -> 12935 | ... N30: =OFFSET($C$3,(COLUMN()-COLUMN($C$30))*2,(COLUMN()-COLUMN($C$30))) -> 14383
A31: Old | B31: Users | C31: =C28-C30 -> 0 | D31: =D28-D30 -> 1404 | E31: =E28-E30 -> 2567 | F31: =F28-F30 -> 3622 | G31: =G28-G30 -> 3335 | H31: =H28-H30 -> 3730 | I31: =I28-I30 -> 3766 | J31: =J28-J30 -> 3128 | ... N31: =N28-N30 -> 3227
A32: Old | B32: Users % | C32: =C31/C28 -> 0 | D32: =D31/D28 -> 0.080680382 | E32: =E31/E28 -> 0.11821866 | F32: =F31/F28 -> 0.1576016 | G32: =G31/G28 -> 0.15214416 | H32: =H31/H28 -> 0.2131185 | I32: =I31/I28 -> 0.26300719 | J32: =J31/J28 -> 0.19473324 | ... N32: =N31/N28 -> 0.18324815
A34: New Users | B34: Revenue | C34: =OFFSET($C$2,(COLUMN()-COLUMN($C$34))*2,(COLUMN()-COLUMN($C$34))) -> 3470489 | D34: =OFFSET($C$2,(COLUMN()-COLUMN($C$34))*2,(COLUMN()-COLUMN($C$34))) -> 5119928.2 | E34: =OFFSET($C$2,(COLUMN()-COLUMN($C$34))*2,(COLUMN()-COLUMN($C$34))) -> 3815355.3 | F34: =OFFSET($C$2,(COLUMN()-COLUMN($C$34))*2,(COLUMN()-COLUMN($C$34))) -> 4547888.8 | G34: =OFFSET($C$2,(COLUMN()-COLUMN($C$34))*2,(COLUMN()-COLUMN($C$34))) -> 2906573.5 | H34: =OFFSET($C$2,(COLUMN()-COLUMN($C$34))*2,(COLUMN()-COLUMN($C$34))) -> 2178295.9 | I34: =OFFSET($C$2,(COLUMN()-COLUMN($C$34))*2,(COLUMN()-COLUMN($C$34))) -> 2894310.4 | J34: =OFFSET($C$2,(COLUMN()-COLUMN($C$34))*2,(COLUMN()-COLUMN($C$34))) -> 3252521.6 | ... N34: =OFFSET($C$2,(COLUMN()-COLUMN($C$34))*2,(COLUMN()-COLUMN($C$34))) -> 2727451.8
A35: Old Users | B35: Revenue | C35: =C27-C34 -> 0 | D35: =D27-D34 -> 4531845.7 | E35: =E27-E34 -> 5267754.2 | F35: =F27-F34 -> 6162341.2 | G35: =G27-G34 -> 8942618.2 | H35: =H27-H34 -> 8317458 | I35: =I27-I34 -> 8048223.2 | J35: =J27-J34 -> 10148337 | ... N35: =N27-N34 -> 22310246
A36: Old Users | B36: Revenue % | C36: =C35/C27 -> 0 | D36: =D35/D27 -> 0.469535 | E36: =E35/E27 -> 0.57995053 | F36: =F35/F27 -> 0.57536964 | G36: =G35/G27 -> 0.7547028 | H36: =H35/H27 -> 0.79245932 | I36: =I35/I27 -> 0.73549907 | J36: =J35/J27 -> 0.75729005 | ... N36: =N35/N27 -> 0.89106619
A38: New Users | B38: RPU | C38: =C34/C30 -> 292.35018 | D38: =D34/D30 -> 320.03552 | E38: =E34/E30 -> 199.26648 | F38: =F34/F30 -> 234.91161 | G38: =G34/G30 -> 156.39352 | H38: =H34/H30 -> 158.16845 | I38: =I34/I30 -> 274.26422 | J38: =J34/J30 -> 251.45123 | ... N38: =N34/N30 -> 189.63025
A39: Old Users | B39: RPU | C39: =IFERROR(C35/C31,0) -> 0 | D39: =D35/D31 -> 3227.8103 | E39: =E35/E31 -> 2052.1052 | F39: =F35/F31 -> 1701.3642 | G39: =G35/G31 -> 2681.4447 | H39: =H35/H31 -> 2229.8815 | I39: =I35/I31 -> 2137.0747 | J39: =J35/J31 -> 3244.3532 | K39: =K35/K31 -> 3476.7186 | ... N39: =N35/N31 -> 6913.6183
A40: Overall Users | B40: RPU | C40: =C27/C28 -> 292.35018 | D40: =D27/D28 -> 554.6359 | E40: =E27/E28 -> 418.30659 | F40: =F27/F28 -> 466.02689 | G40: =G27/G28 -> 540.56532 | H40: =H27/H28 -> 599.68883 | I40: =I27/I28 -> 764.19677 | J40: =J27/J28 -> 834.26871 | ... N40: =N27/N28 -> 1421.7886

Sheet Monthly_Retention_Numbers
A1: Reg. Month | B1: New Users | C1: M0 | D1: M1 | E1: M2 | F1: M3 | G1: M4 | H1: M5 | I1: M6 | J1: M7 | K1: M8 | L1: M9 | M1: M10 | N1: M11
A2: 44652 | B2: {=TRANSPOSE('Monthly_Cohort_&_Matrix'!C30:N30)} -> 11871 | C2: {=IFERROR(INDEX('Monthly_Cohort_&_Matrix'!$C:$N,(ROW()-2)*2+3,COLUMN()+ROW()-4),"")} -> 11871 | D2: {=IFERROR(INDEX('Monthly_Cohort_&_Matrix'!$C:$N,(ROW()-2)*2+3,COLUMN()+ROW()-4),"")} -> 1404 | E2: {=IFERROR(INDEX('Monthly_Cohort_&_Matrix'!$C:$N,(ROW()-2)*2+3,COLUMN()+ROW()-4),"")} -> 643 | F2: {=IFERROR(INDEX('Monthly_Cohort_&_Matrix'!$C:$N,(ROW()-2)*2+3,COLUMN()+ROW()-4),"")} -> 525 | G2: {=IFERROR(INDEX('Monthly_Cohort_&_Matrix'!$C:$N,(ROW()-2)*2+3,COLUMN()+ROW()-4),"")} -> 341 | H2: {=IFERROR(INDEX('Monthly_Cohort_&_Matrix'!$C:$N,(ROW()-2)*2+3,COLUMN()+ROW()-4),"")} -> 329 | I2: {=IFERROR(INDEX('Monthly_Cohort_&_Matrix'!$C:$N,(ROW()-2)*2+3,COLUMN()+ROW()-4),"")} -> 328 | J2: {=IFERROR(INDEX('Monthly_Cohort_&_Matrix'!$C:$N,(ROW()-2)*2+3,COLUMN()+ROW()-4),"")} -> 242 | ... N2: {=IFERROR(INDEX('Monthly_Cohort_&_Matrix'!$C:$N,(ROW()-2)*2+3,COLUMN()+ROW()-4),"")} -> 164
A3: 44682 | B3: 15998 | C3: {=IFERROR(INDEX('Monthly_Cohort_&_Matrix'!$C:$N,(ROW()-2)*2+3,COLUMN()+ROW()-4),"")} -> 15998 | D3: {=IFERROR(INDEX('Monthly_Cohort_&_Matrix'!$C:$N,(ROW()-2)*2+3,COLUMN()+ROW()-4),"")} -> 1924 | E3: {=IFERROR(INDEX('Monthly_Cohort_&_Matrix'!$C:$N,(ROW()-2)*2+3,COLUMN()+ROW()-4),"")} -> 916 | F3: {=IFERROR(INDEX('Monthly_Cohort_&_Matrix'!$C:$N,(ROW()-2)*2+3,COLUMN()+ROW()-4),"")} -> 613 | G3: {=IFERROR(INDEX('Monthly_Cohort_&_Matrix'!$C:$N,(ROW()-2)*2+3,COLUMN()+ROW()-4),"")} -> 484 | H3: {=IFERROR(INDEX('Monthly_Cohort_&_Matrix'!$C:$N,(ROW()-2)*2+3,COLUMN()+ROW()-4),"")} -> 475 | I3: {=IFERROR(INDEX('Monthly_Cohort_&_Matrix'!$C:$N,(ROW()-2)*2+3,COLUMN()+ROW()-4),"")} -> 358 | J3: {=IFERROR(INDEX('Monthly_Cohort_&_Matrix'!$C:$N,(ROW()-2)*2+3,COLUMN()+ROW()-4),"")} -> 336 | ... N3: {=IFERROR(INDEX('Monthly_Cohort_&_Matrix'!$C:$N,(ROW()-2)*2+3,COLUMN()+ROW()-4),"")}
A4: 44713 | B4: 19147 | C4: {=IFERROR(INDEX('Monthly_Cohort_&_Matrix'!$C:$N,(ROW()-2)*2+3,COLUMN()+ROW()-4),"")} -> 19147 | D4: {=IFERROR(INDEX('Monthly_Cohort_&_Matrix'!$C:$N,(ROW()-2)*2+3,COLUMN()+ROW()-4),"")} -> 2181 | E4: {=IFERROR(INDEX('Monthly_Cohort_&_Matrix'!$C:$N,(ROW()-2)*2+3,COLUMN()+ROW()-4),"")} -> 693 | F4: {=IFERROR(INDEX('Monthly_Cohort_&_Matrix'!$C:$N,(ROW()-2)*2+3,COLUMN()+ROW()-4),"")} -> 590 | G4: {=IFERROR(INDEX('Monthly_Cohort_&_Matrix'!$C:$N,(ROW()-2)*2+3,COLUMN()+ROW()-4),"")} -> 507 | H4: {=IFERROR(INDEX('Monthly_Cohort_&_Matrix'!$C:$N,(ROW()-2)*2+3,COLUMN()+ROW()-4),"")} -> 333 | I4: {=IFERROR(INDEX('Monthly_Cohort_&_Matrix'!$C:$N,(ROW()-2)*2+3,COLUMN()+ROW()-4),"")} -> 303 | J4: {=IFERROR(INDEX('Monthly_Cohort_&_Matrix'!$C:$N,(ROW()-2)*2+3,COLUMN()+ROW()-4),"")} -> 254 | ... N4: {=IFERROR(INDEX('Monthly_Cohort_&_Matrix'!$C:$N,(ROW()-2)*2+3,COLUMN()+ROW()-4),"")}
A5: 44743 | B5: 19360 | C5: {=IFERROR(INDEX('Monthly_Cohort_&_Matrix'!$C:$N,(ROW()-2)*2+3,COLUMN()+ROW()-4),"")} -> 19360 | D5: {=IFERROR(INDEX('Monthly_Cohort_&_Matrix'!$C:$N,(ROW()-2)*2+3,COLUMN()+ROW()-4),"")} -> 1688 | E5: {=IFERROR(INDEX('Monthly_Cohort_&_Matrix'!$C:$N,(ROW()-2)*2+3,COLUMN()+ROW()-4),"")} -> 831 | F5: {=IFERROR(INDEX('Monthly_Cohort_&_Matrix'!$C:$N,(ROW()-2)*2+3,COLUMN()+ROW()-4),"")} -> 632 | G5: {=IFERROR(INDEX('Monthly_Cohort_&_Matrix'!$C:$N,(ROW()-2)*2+3,COLUMN()+ROW()-4),"")} -> 405 | H5: {=IFERROR(INDEX('Monthly_Cohort_&_Matrix'!$C:$N,(ROW()-2)*2+3,COLUMN()+ROW()-4),"")} -> 357 | I5: {=IFERROR(INDEX('Monthly_Cohort_&_Matrix'!$C:$N,(ROW()-2)*2+3,COLUMN()+ROW()-4),"")} -> 325 | J5: {=IFERROR(INDEX('Monthly_Cohort_&_Matrix'!$C:$N,(ROW()-2)*2+3,COLUMN()+ROW()-4),"")} -> 286 | ... N5: {=IFERROR(INDEX('Monthly_Cohort_&_Matrix'!$C:$N,(ROW()-2)*2+3,COLUMN()+ROW()-4),"")}
A6: 44774 | B6: 18585 | C6: {=IFERROR(INDEX('Monthly_Cohort_&_Matrix'!$C:$N,(ROW()-2)*2+3,COLUMN()+ROW()-4),"")} -> 18585 | D6: {=IFERROR(INDEX('Monthly_Cohort_&_Matrix'!$C:$N,(ROW()-2)*2+3,COLUMN()+ROW()-4),"")} -> 1496 | E6: {=IFERROR(INDEX('Monthly_Cohort_&_Matrix'!$C:$N,(ROW()-2)*2+3,COLUMN()+ROW()-4),"")} -> 726 | F6: {=IFERROR(INDEX('Monthly_Cohort_&_Matrix'!$C:$N,(ROW()-2)*2+3,COLUMN()+ROW()-4),"")} -> 387 | G6: {=IFERROR(INDEX('Monthly_Cohort_&_Matrix'!$C:$N,(ROW()-2)*2+3,COLUMN()+ROW()-4),"")} -> 366 | H6: {=IFERROR(INDEX('Monthly_Cohort_&_Matrix'!$C:$N,(ROW()-2)*2+3,COLUMN()+ROW()-4),"")} -> 287 | I6: {=IFERROR(INDEX('Monthly_Cohort_&_Matrix'!$C:$N,(ROW()-2)*2+3,COLUMN()+ROW()-4),"")} -> 237 | J6: {=IFERROR(INDEX('Monthly_Cohort_&_Matrix'!$C:$N,(ROW()-2)*2+3,COLUMN()+ROW()-4),"")} -> 199 | ... N6: {=IFERROR(INDEX('Monthly_Cohort_&_Matrix'!$C:$N,(ROW()-2)*2+3,COLUMN()+ROW()-4),"")}
A7: 44805 | B7: 13772 | C7: {=IFERROR(INDEX('Monthly_Cohort_&_Matrix'!$C:$N,(ROW()-2)*2+3,COLUMN()+ROW()-4),"")} -> 13772 | D7: {=IFERROR(INDEX('Monthly_Cohort_&_Matrix'!$C:$N,(ROW()-2)*2+3,COLUMN()+ROW()-4),"")} -> 1098 | E7: {=IFERROR(INDEX('Monthly_Cohort_&_Matrix'!$C:$N,(ROW()-2)*2+3,COLUMN()+ROW()-4),"")} -> 451 | F7: {=IFERROR(INDEX('Monthly_Cohort_&_Matrix'!$C:$N,(ROW()-2)*2+3,COLUMN()+ROW()-4),"")} -> 336 | G7: {=IFERROR(INDEX('Monthly_Cohort_&_Matrix'!$C:$N,(ROW()-2)*2+3,COLUMN()+ROW()-4),"")} -> 265 | H7: {=IFERROR(INDEX('Monthly_Cohort_&_Matrix'!$C:$N,(ROW()-2)*2+3,COLUMN()+ROW()-4),"")} -> 211 | I7: {=IFERROR(INDEX('Monthly_Cohort_&_Matrix'!$C:$N,(ROW()-2)*2+3,COLUMN()+ROW()-4),"")} -> 172 | J7: {=IFERROR(INDEX('Monthly_Cohort_&_Matrix'!$C:$N,(ROW()-2)*2+3,COLUMN()+ROW()-4),"")} | ... N7: {=IFERROR(INDEX('Monthly_Cohort_&_Matrix'!$C:$N,(ROW()-2)*2+3,COLUMN()+ROW()-4),"")}
A8: 44835 | B8: 10553 | C8: {=IFERROR(INDEX('Monthly_Cohort_&_Matrix'!$C:$N,(ROW()-2)*2+3,COLUMN()+ROW()-4),"")} -> 10553 | D8: {=IFERROR(INDEX('Monthly_Cohort_&_Matrix'!$C:$N,(ROW()-2)*2+3,COLUMN()+ROW()-4),"")} -> 952 | E8: {=IFERROR(INDEX('Monthly_Cohort_&_Matrix'!$C:$N,(ROW()-2)*2+3,COLUMN()+ROW()-4),"")} -> 449 | F8: {=IFERROR(INDEX('Monthly_Cohort_&_Matrix'!$C:$N,(ROW()-2)*2+3,COLUMN()+ROW()-4),"")} -> 234 | G8: {=IFERROR(INDEX('Monthly_Cohort_&_Matrix'!$C:$N,(ROW()-2)*2+3,COLUMN()+ROW()-4),"")} -> 185 | H8: {=IFERROR(INDEX('Monthly_Cohort_&_Matrix'!$C:$N,(ROW()-2)*2+3,COLUMN()+ROW()-4),"")} -> 147 | I8: {=IFERROR(INDEX('Monthly_Cohort_&_Matrix'!$C:$N,(ROW()-2)*2+3,COLUMN()+ROW()-4),"")} | J8: {=IFERROR(INDEX('Monthly_Cohort_&_Matrix'!$C:$N,(ROW()-2)*2+3,COLUMN()+ROW()-4),"")} | ... N8: {=IFERROR(INDEX('Monthly_Cohort_&_Matrix'!$C:$N,(ROW()-2)*2+3,COLUMN()+ROW()-4),"")}
A9: 44866 | B9: 12935 | C9: {=IFERROR(INDEX('Monthly_Cohort_&_Matrix'!$C:$N,(ROW()-2)*2+3,COLUMN()+ROW()-4),"")} -> 12935 | D9: {=IFERROR(INDEX('Monthly_Cohort_&_Matrix'!$C:$N,(ROW()-2)*2+3,COLUMN()+ROW()-4),"")} -> 1222 | E9: {=IFERROR(INDEX('Monthly_Cohort_&_Matrix'!$C:$N,(ROW()-2)*2+3,COLUMN()+ROW()-4),"")} -> 415 | F9: {=IFERROR(INDEX('Monthly_Cohort_&_Matrix'!$C:$N,(ROW()-2)*2+3,COLUMN()+ROW()-4),"")} -> 273 | G9: {=IFERROR(INDEX('Monthly_Cohort_&_Matrix'!$C:$N,(ROW()-2)*2+3,COLUMN()+ROW()-4),"")} -> 226 | H9: {=IFERROR(INDEX('Monthly_Cohort_&_Matrix'!$C:$N,(ROW()-2)*2+3,COLUMN()+ROW()-4),"")} | I9: {=IFERROR(INDEX('Monthly_Cohort_&_Matrix'!$C:$N,(ROW()-2)*2+3,COLUMN()+ROW()-4),"")} | J9: {=IFERROR(INDEX('Monthly_Cohort_&_Matrix'!$C:$N,(ROW()-2)*2+3,COLUMN()+ROW()-4),"")} | ... N9: {=IFERROR(INDEX('Monthly_Cohort_&_Matrix'!$C:$N,(ROW()-2)*2+3,COLUMN()+ROW()-4),"")}
A10: 44896 | B10: 10997 | C10: {=IFERROR(INDEX('Monthly_Cohort_&_Matrix'!$C:$N,(ROW()-2)*2+3,COLUMN()+ROW()-4),"")} -> 10997 | D10: {=IFERROR(INDEX('Monthly_Cohort_&_Matrix'!$C:$N,(ROW()-2)*2+3,COLUMN()+ROW()-4),"")} -> 860 | E10: {=IFERROR(INDEX('Monthly_Cohort_&_Matrix'!$C:$N,(ROW()-2)*2+3,COLUMN()+ROW()-4),"")} -> 373 | F10: {=IFERROR(INDEX('Monthly_Cohort_&_Matrix'!$C:$N,(ROW()-2)*2+3,COLUMN()+ROW()-4),"")} -> 276 | G10: {=IFERROR(INDEX('Monthly_Cohort_&_Matrix'!$C:$N,(ROW()-2)*2+3,COLUMN()+ROW()-4),"")} | H10: {=IFERROR(INDEX('Monthly_Cohort_&_Matrix'!$C:$N,(ROW()-2)*2+3,COLUMN()+ROW()-4),"")} | I10: {=IFERROR(INDEX('Monthly_Cohort_&_Matrix'!$C:$N,(ROW()-2)*2+3,COLUMN()+ROW()-4),"")} | J10: {=IFERROR(INDEX('Monthly_Cohort_&_Matrix'!$C:$N,(ROW()-2)*2+3,COLUMN()+ROW()-4),"")} | ... N10: {=IFERROR(INDEX('Monthly_Cohort_&_Matrix'!$C:$N,(ROW()-2)*2+3,COLUMN()+ROW()-4),"")}
A11: 44927 | B11: 11697 | C11: {=IFERROR(INDEX('Monthly_Cohort_&_Matrix'!$C:$N,(ROW()-2)*2+3,COLUMN()+ROW()-4),"")} -> 11697 | D11: {=IFERROR(INDEX('Monthly_Cohort_&_Matrix'!$C:$N,(ROW()-2)*2+3,COLUMN()+ROW()-4),"")} -> 996 | E11: {=IFERROR(INDEX('Monthly_Cohort_&_Matrix'!$C:$N,(ROW()-2)*2+3,COLUMN()+ROW()-4),"")} -> 454 | F11: {=IFERROR(INDEX('Monthly_Cohort_&_Matrix'!$C:$N,(ROW()-2)*2+3,COLUMN()+ROW()-4),"")} | G11: {=IFERROR(INDEX('Monthly_Cohort_&_Matrix'!$C:$N,(ROW()-2)*2+3,COLUMN()+ROW()-4),"")} | H11: {=IFERROR(INDEX('Monthly_Cohort_&_Matrix'!$C:$N,(ROW()-2)*2+3,COLUMN()+ROW()-4),"")} | I11: {=IFERROR(INDEX('Monthly_Cohort_&_Matrix'!$C:$N,(ROW()-2)*2+3,COLUMN()+ROW()-4),"")} | J11: {=IFERROR(INDEX('Monthly_Cohort_&_Matrix'!$C:$N,(ROW()-2)*2+3,COLUMN()+ROW()-4),"")} | ... N11: {=IFERROR(INDEX('Monthly_Cohort_&_Matrix'!$C:$N,(ROW()-2)*2+3,COLUMN()+ROW()-4),"")}
A12: 44958 | B12: 11724 | C12: {=IFERROR(INDEX('Monthly_Cohort_&_Matrix'!$C:$N,(ROW()-2)*2+3,COLUMN()+ROW()-4),"")} -> 11724 | D12: {=IFERROR(INDEX('Monthly_Cohort_&_Matrix'!$C:$N,(ROW()-2)*2+3,COLUMN()+ROW()-4),"")} -> 855 | E12: {=IFERROR(INDEX('Monthly_Cohort_&_Matrix'!$C:$N,(ROW()-2)*2+3,COLUMN()+ROW()-4),"")} | F12: {=IFERROR(INDEX('Monthly_Cohort_&_Matrix'!$C:$N,(ROW()-2)*2+3,COLUMN()+ROW()-4),"")} | G12: {=IFERROR(INDEX('Monthly_Cohort_&_Matrix'!$C:$N,(ROW()-2)*2+3,COLUMN()+ROW()-4),"")} | H12: {=IFERROR(INDEX('Monthly_Cohort_&_Matrix'!$C:$N,(ROW()-2)*2+3,COLUMN()+ROW()-4),"")} | I12: {=IFERROR(INDEX('Monthly_Cohort_&_Matrix'!$C:$N,(ROW()-2)*2+3,COLUMN()+ROW()-4),"")} | J12: {=IFERROR(INDEX('Monthly_Cohort_&_Matrix'!$C:$N,(ROW()-2)*2+3,COLUMN()+ROW()-4),"")} | ... N12: {=IFERROR(INDEX('Monthly_Cohort_&_Matrix'!$C:$N,(ROW()-2)*2+3,COLUMN()+ROW()-4),"")}
A13: 44986 | B13: 14383 | C13: {=IFERROR(INDEX('Monthly_Cohort_&_Matrix'!$C:$N,(ROW()-2)*2+3,COLUMN()+ROW()-4),"")} -> 14383 | D13: {=IFERROR(INDEX('Monthly_Cohort_&_Matrix'!$C:$N,(ROW()-2)*2+3,COLUMN()+ROW()-4),"")} | E13: {=IFERROR(INDEX('Monthly_Cohort_&_Matrix'!$C:$N,(ROW()-2)*2+3,COLUMN()+ROW()-4),"")} | F13: {=IFERROR(INDEX('Monthly_Cohort_&_Matrix'!$C:$N,(ROW()-2)*2+3,COLUMN()+ROW()-4),"")} | G13: {=IFERROR(INDEX('Monthly_Cohort_&_Matrix'!$C:$N,(ROW()-2)*2+3,COLUMN()+ROW()-4),"")} | H13: {=IFERROR(INDEX('Monthly_Cohort_&_Matrix'!$C:$N,(ROW()-2)*2+3,COLUMN()+ROW()-4),"")} | I13: {=IFERROR(INDEX('Monthly_Cohort_&_Matrix'!$C:$N,(ROW()-2)*2+3,COLUMN()+ROW()-4),"")} | J13: {=IFERROR(INDEX('Monthly_Cohort_&_Matrix'!$C:$N,(ROW()-2)*2+3,COLUMN()+ROW()-4),"")} | ... N13: {=IFERROR(INDEX('Monthly_Cohort_&_Matrix'!$C:$N,(ROW()-2)*2+3,COLUMN()+ROW()-4),"")}
A16: Reg. Month | B16: New Users Rev. | C16: M0 | D16: M1 | E16: M2 | F16: M3 | G16: M4 | H16: M5 | I16: M6 | J16: M7 | K16: M8 | L16: M9 | M16: M10 | N16: M11
A17: 44652 | B17: {=TRANSPOSE('Monthly_Cohort_&_Matrix'!C34:N34)} -> 3470489 | C17: {=IFERROR(INDEX('Monthly_Cohort_&_Matrix'!$C:$N,(ROW()-17)*2+2,COLUMN()+ROW()-19),"")} -> 3470489 | D17: {=IFERROR(INDEX('Monthly_Cohort_&_Matrix'!$C:$N,(ROW()-17)*2+2,COLUMN()+ROW()-19),"")} -> 4531845.7 | E17: {=IFERROR(INDEX('Monthly_Cohort_&_Matrix'!$C:$N,(ROW()-17)*2+2,COLUMN()+ROW()-19),"")} -> 2016024.7 | F17: {=IFERROR(INDEX('Monthly_Cohort_&_Matrix'!$C:$N,(ROW()-17)*2+2,COLUMN()+ROW()-19),"")} -> 1479962.3 | G17: {=IFERROR(INDEX('Monthly_Cohort_&_Matrix'!$C:$N,(ROW()-17)*2+2,COLUMN()+ROW()-19),"")} -> 1504660.4 | H17: {=IFERROR(INDEX('Monthly_Cohort_&_Matrix'!$C:$N,(ROW()-17)*2+2,COLUMN()+ROW()-19),"")} -> 1611245.6 | I17: {=IFERROR(INDEX('Monthly_Cohort_&_Matrix'!$C:$N,(ROW()-17)*2+2,COLUMN()+ROW()-19),"")} -> 1522136.7 | J17: {=IFERROR(INDEX('Monthly_Cohort_&_Matrix'!$C:$N,(ROW()-17)*2+2,COLUMN()+ROW()-19),"")} -> 1431240.4 | ... N17: {=IFERROR(INDEX('Monthly_Cohort_&_Matrix'!$C:$N,(ROW()-17)*2+2,COLUMN()+ROW()-19),"")} -> 1613196.9
A18: 44682 | B18: 5119928.2 | C18: {=IFERROR(INDEX('Monthly_Cohort_&_Matrix'!$C:$N,(ROW()-17)*2+2,COLUMN()+ROW()-19),"")} -> 5119928.2 | D18: {=IFERROR(INDEX('Monthly_Cohort_&_Matrix'!$C:$N,(ROW()-17)*2+2,COLUMN()+ROW()-19),"")} -> 3251729.4 | E18: {=IFERROR(INDEX('Monthly_Cohort_&_Matrix'!$C:$N,(ROW()-17)*2+2,COLUMN()+ROW()-19),"")} -> 2104764.6 | F18: {=IFERROR(INDEX('Monthly_Cohort_&_Matrix'!$C:$N,(ROW()-17)*2+2,COLUMN()+ROW()-19),"")} -> 1837881.9 | G18: {=IFERROR(INDEX('Monthly_Cohort_&_Matrix'!$C:$N,(ROW()-17)*2+2,COLUMN()+ROW()-19),"")} -> 1139201.3 | H18: {=IFERROR(INDEX('Monthly_Cohort_&_Matrix'!$C:$N,(ROW()-17)*2+2,COLUMN()+ROW()-19),"")} -> 642896.15 | I18: {=IFERROR(INDEX('Monthly_Cohort_&_Matrix'!$C:$N,(ROW()-17)*2+2,COLUMN()+ROW()-19),"")} -> 748966.78 | J18: {=IFERROR(INDEX('Monthly_Cohort_&_Matrix'!$C:$N,(ROW()-17)*2+2,COLUMN()+ROW()-19),"")} -> 1110431.3 | ... N18: {=IFERROR(INDEX('Monthly_Cohort_&_Matrix'!$C:$N,(ROW()-17)*2+2,COLUMN()+ROW()-19),"")}
A19: 44713 | B19: 3815355.3 | C19: {=IFERROR(INDEX('Monthly_Cohort_&_Matrix'!$C:$N,(ROW()-17)*2+2,COLUMN()+ROW()-19),"")} -> 3815355.3 | D19: {=IFERROR(INDEX('Monthly_Cohort_&_Matrix'!$C:$N,(ROW()-17)*2+2,COLUMN()+ROW()-19),"")} -> 2577614.2 | E19: {=IFERROR(INDEX('Monthly_Cohort_&_Matrix'!$C:$N,(ROW()-17)*2+2,COLUMN()+ROW()-19),"")} -> 1433445.4 | F19: {=IFERROR(INDEX('Monthly_Cohort_&_Matrix'!$C:$N,(ROW()-17)*2+2,COLUMN()+ROW()-19),"")} -> 1390421.2 | G19: {=IFERROR(INDEX('Monthly_Cohort_&_Matrix'!$C:$N,(ROW()-17)*2+2,COLUMN()+ROW()-19),"")} -> 1348763.1 | H19: {=IFERROR(INDEX('Monthly_Cohort_&_Matrix'!$C:$N,(ROW()-17)*2+2,COLUMN()+ROW()-19),"")} -> 840880.32 | I19: {=IFERROR(INDEX('Monthly_Cohort_&_Matrix'!$C:$N,(ROW()-17)*2+2,COLUMN()+ROW()-19),"")} -> 749196.5 | J19: {=IFERROR(INDEX('Monthly_Cohort_&_Matrix'!$C:$N,(ROW()-17)*2+2,COLUMN()+ROW()-19),"")} -> 663578.6 | ... N19: {=IFERROR(INDEX('Monthly_Cohort_&_Matrix'!$C:$N,(ROW()-17)*2+2,COLUMN()+ROW()-19),"")}
A20: 44743 | B20: 4547888.8 | C20: {=IFERROR(INDEX('Monthly_Cohort_&_Matrix'!$C:$N,(ROW()-17)*2+2,COLUMN()+ROW()-19),"")} -> 4547888.8 | D20: {=IFERROR(INDEX('Monthly_Cohort_&_Matrix'!$C:$N,(ROW()-17)*2+2,COLUMN()+ROW()-19),"")} -> 4166630.6 | E20: {=IFERROR(INDEX('Monthly_Cohort_&_Matrix'!$C:$N,(ROW()-17)*2+2,COLUMN()+ROW()-19),"")} -> 2402552.6 | F20: {=IFERROR(INDEX('Monthly_Cohort_&_Matrix'!$C:$N,(ROW()-17)*2+2,COLUMN()+ROW()-19),"")} -> 1811911.9 | G20: {=IFERROR(INDEX('Monthly_Cohort_&_Matrix'!$C:$N,(ROW()-17)*2+2,COLUMN()+ROW()-19),"")} -> 2653527.7 | H20: {=IFERROR(INDEX('Monthly_Cohort_&_Matrix'!$C:$N,(ROW()-17)*2+2,COLUMN()+ROW()-19),"")} -> 3125232.7 | I20: {=IFERROR(INDEX('Monthly_Cohort_&_Matrix'!$C:$N,(ROW()-17)*2+2,COLUMN()+ROW()-19),"")} -> 2436043.4 | J20: {=IFERROR(INDEX('Monthly_Cohort_&_Matrix'!$C:$N,(ROW()-17)*2+2,COLUMN()+ROW()-19),"")} -> 1559146.1 | ... N20: {=IFERROR(INDEX('Monthly_Cohort_&_Matrix'!$C:$N,(ROW()-17)*2+2,COLUMN()+ROW()-19),"")}
A21: 44774 | B21: 2906573.5 | C21: {=IFERROR(INDEX('Monthly_Cohort_&_Matrix'!$C:$N,(ROW()-17)*2+2,COLUMN()+ROW()-19),"")} -> 2906573.5 | D21: {=IFERROR(INDEX('Monthly_Cohort_&_Matrix'!$C:$N,(ROW()-17)*2+2,COLUMN()+ROW()-19),"")} -> 1774037.2 | E21: {=IFERROR(INDEX('Monthly_Cohort_&_Matrix'!$C:$N,(ROW()-17)*2+2,COLUMN()+ROW()-19),"")} -> 1403062.7 | F21: {=IFERROR(INDEX('Monthly_Cohort_&_Matrix'!$C:$N,(ROW()-17)*2+2,COLUMN()+ROW()-19),"")} -> 1113653.4 | G21: {=IFERROR(INDEX('Monthly_Cohort_&_Matrix'!$C:$N,(ROW()-17)*2+2,COLUMN()+ROW()-19),"")} -> 1237597.1 | H21: {=IFERROR(INDEX('Monthly_Cohort_&_Matrix'!$C:$N,(ROW()-17)*2+2,COLUMN()+ROW()-19),"")} -> 1538336.2 | I21: {=IFERROR(INDEX('Monthly_Cohort_&_Matrix'!$C:$N,(ROW()-17)*2+2,COLUMN()+ROW()-19),"")} -> 705618.63 | J21: {=IFERROR(INDEX('Monthly_Cohort_&_Matrix'!$C:$N,(ROW()-17)*2+2,COLUMN()+ROW()-19),"")} -> 926147.72 | ... N21: {=IFERROR(INDEX('Monthly_Cohort_&_Matrix'!$C:$N,(ROW()-17)*2+2,COLUMN()+ROW()-19),"")}
A22: 44805 | B22: 2178295.9 | C22: {=IFERROR(INDEX('Monthly_Cohort_&_Matrix'!$C:$N,(ROW()-17)*2+2,COLUMN()+ROW()-19),"")} -> 2178295.9 | D22: {=IFERROR(INDEX('Monthly_Cohort_&_Matrix'!$C:$N,(ROW()-17)*2+2,COLUMN()+ROW()-19),"")} -> 1319452.6 | E22: {=IFERROR(INDEX('Monthly_Cohort_&_Matrix'!$C:$N,(ROW()-17)*2+2,COLUMN()+ROW()-19),"")} -> 937420.57 | F22: {=IFERROR(INDEX('Monthly_Cohort_&_Matrix'!$C:$N,(ROW()-17)*2+2,COLUMN()+ROW()-19),"")} -> 779976.65 | G22: {=IFERROR(INDEX('Monthly_Cohort_&_Matrix'!$C:$N,(ROW()-17)*2+2,COLUMN()+ROW()-19),"")} -> 1073896 | H22: {=IFERROR(INDEX('Monthly_Cohort_&_Matrix'!$C:$N,(ROW()-17)*2+2,COLUMN()+ROW()-19),"")} -> 519091.13 | I22: {=IFERROR(INDEX('Monthly_Cohort_&_Matrix'!$C:$N,(ROW()-17)*2+2,COLUMN()+ROW()-19),"")} -> 416146.64 | J22: {=IFERROR(INDEX('Monthly_Cohort_&_Matrix'!$C:$N,(ROW()-17)*2+2,COLUMN()+ROW()-19),"")} | ... N22: {=IFERROR(INDEX('Monthly_Cohort_&_Matrix'!$C:$N,(ROW()-17)*2+2,COLUMN()+ROW()-19),"")}
A23: 44835 | B23: 2894310.4 | C23: {=IFERROR(INDEX('Monthly_Cohort_&_Matrix'!$C:$N,(ROW()-17)*2+2,COLUMN()+ROW()-19),"")} -> 2894310.4 | D23: {=IFERROR(INDEX('Monthly_Cohort_&_Matrix'!$C:$N,(ROW()-17)*2+2,COLUMN()+ROW()-19),"")} -> 2422647.6 | E23: {=IFERROR(INDEX('Monthly_Cohort_&_Matrix'!$C:$N,(ROW()-17)*2+2,COLUMN()+ROW()-19),"")} -> 1103806.6 | F23: {=IFERROR(INDEX('Monthly_Cohort_&_Matrix'!$C:$N,(ROW()-17)*2+2,COLUMN()+ROW()-19),"")} -> 825014.41 | G23: {=IFERROR(INDEX('Monthly_Cohort_&_Matrix'!$C:$N,(ROW()-17)*2+2,COLUMN()+ROW()-19),"")} -> 729020.05 | H23: {=IFERROR(INDEX('Monthly_Cohort_&_Matrix'!$C:$N,(ROW()-17)*2+2,COLUMN()+ROW()-19),"")} -> 1049514.4 | I23: {=IFERROR(INDEX('Monthly_Cohort_&_Matrix'!$C:$N,(ROW()-17)*2+2,COLUMN()+ROW()-19),"")} | J23: {=IFERROR(INDEX('Monthly_Cohort_&_Matrix'!$C:$N,(ROW()-17)*2+2,COLUMN()+ROW()-19),"")} | ... N23: {=IFERROR(INDEX('Monthly_Cohort_&_Matrix'!$C:$N,(ROW()-17)*2+2,COLUMN()+ROW()-19),"")}
A24: 44866 | B24: 3252521.6 | C24: {=IFERROR(INDEX('Monthly_Cohort_&_Matrix'!$C:$N,(ROW()-17)*2+2,COLUMN()+ROW()-19),"")} -> 3252521.6 | D24: {=IFERROR(INDEX('Monthly_Cohort_&_Matrix'!$C:$N,(ROW()-17)*2+2,COLUMN()+ROW()-19),"")} -> 2952210.7 | E24: {=IFERROR(INDEX('Monthly_Cohort_&_Matrix'!$C:$N,(ROW()-17)*2+2,COLUMN()+ROW()-19),"")} -> 1582011.8 | F24: {=IFERROR(INDEX('Monthly_Cohort_&_Matrix'!$C:$N,(ROW()-17)*2+2,COLUMN()+ROW()-19),"")} -> 1297248.4 | G24: {=IFERROR(INDEX('Monthly_Cohort_&_Matrix'!$C:$N,(ROW()-17)*2+2,COLUMN()+ROW()-19),"")} -> 1838872.5 | H24: {=IFERROR(INDEX('Monthly_Cohort_&_Matrix'!$C:$N,(ROW()-17)*2+2,COLUMN()+ROW()-19),"")} | I24: {=IFERROR(INDEX('Monthly_Cohort_&_Matrix'!$C:$N,(ROW()-17)*2+2,COLUMN()+ROW()-19),"")} | J24: {=IFERROR(INDEX('Monthly_Cohort_&_Matrix'!$C:$N,(ROW()-17)*2+2,COLUMN()+ROW()-19),"")} | ... N24: {=IFERROR(INDEX('Monthly_Cohort_&_Matrix'!$C:$N,(ROW()-17)*2+2,COLUMN()+ROW()-19),"")}
A25: 44896 | B25: 2753173.2 | C25: {=IFERROR(INDEX('Monthly_Cohort_&_Matrix'!$C:$N,(ROW()-17)*2+2,COLUMN()+ROW()-19),"")} -> 2753173.2 | D25: {=IFERROR(INDEX('Monthly_Cohort_&_Matrix'!$C:$N,(ROW()-17)*2+2,COLUMN()+ROW()-19),"")} -> 4530061.7 | E25: {=IFERROR(INDEX('Monthly_Cohort_&_Matrix'!$C:$N,(ROW()-17)*2+2,COLUMN()+ROW()-19),"")} -> 3856710.7 | F25: {=IFERROR(INDEX('Monthly_Cohort_&_Matrix'!$C:$N,(ROW()-17)*2+2,COLUMN()+ROW()-19),"")} -> 3746109.3 | G25: {=IFERROR(INDEX('Monthly_Cohort_&_Matrix'!$C:$N,(ROW()-17)*2+2,COLUMN()+ROW()-19),"")} | H25: {=IFERROR(INDEX('Monthly_Cohort_&_Matrix'!$C:$N,(ROW()-17)*2+2,COLUMN()+ROW()-19),"")} | I25: {=IFERROR(INDEX('Monthly_Cohort_&_Matrix'!$C:$N,(ROW()-17)*2+2,COLUMN()+ROW()-19),"")} | J25: {=IFERROR(INDEX('Monthly_Cohort_&_Matrix'!$C:$N,(ROW()-17)*2+2,COLUMN()+ROW()-19),"")} | ... N25: {=IFERROR(INDEX('Monthly_Cohort_&_Matrix'!$C:$N,(ROW()-17)*2+2,COLUMN()+ROW()-19),"")}
A26: 44927 | B26: 3024628.9 | C26: {=IFERROR(INDEX('Monthly_Cohort_&_Matrix'!$C:$N,(ROW()-17)*2+2,COLUMN()+ROW()-19),"")} -> 3024628.9 | D26: {=IFERROR(INDEX('Monthly_Cohort_&_Matrix'!$C:$N,(ROW()-17)*2+2,COLUMN()+ROW()-19),"")} -> 3455629.5 | E26: {=IFERROR(INDEX('Monthly_Cohort_&_Matrix'!$C:$N,(ROW()-17)*2+2,COLUMN()+ROW()-19),"")} -> 2403373.9 | F26: {=IFERROR(INDEX('Monthly_Cohort_&_Matrix'!$C:$N,(ROW()-17)*2+2,COLUMN()+ROW()-19),"")} | G26: {=IFERROR(INDEX('Monthly_Cohort_&_Matrix'!$C:$N,(ROW()-17)*2+2,COLUMN()+ROW()-19),"")} | H26: {=IFERROR(INDEX('Monthly_Cohort_&_Matrix'!$C:$N,(ROW()-17)*2+2,COLUMN()+ROW()-19),"")} | I26: {=IFERROR(INDEX('Monthly_Cohort_&_Matrix'!$C:$N,(ROW()-17)*2+2,COLUMN()+ROW()-19),"")} | J26: {=IFERROR(INDEX('Monthly_Cohort_&_Matrix'!$C:$N,(ROW()-17)*2+2,COLUMN()+ROW()-19),"")} | ... N26: {=IFERROR(INDEX('Monthly_Cohort_&_Matrix'!$C:$N,(ROW()-17)*2+2,COLUMN()+ROW()-19),"")}
A27: 44958 | B27: 3526821.4 | C27: {=IFERROR(INDEX('Monthly_Cohort_&_Matrix'!$C:$N,(ROW()-17)*2+2,COLUMN()+ROW()-19),"")} -> 3526821.4 | D27: {=IFERROR(INDEX('Monthly_Cohort_&_Matrix'!$C:$N,(ROW()-17)*2+2,COLUMN()+ROW()-19),"")} -> 5357501.1 | E27: {=IFERROR(INDEX('Monthly_Cohort_&_Matrix'!$C:$N,(ROW()-17)*2+2,COLUMN()+ROW()-19),"")} | F27: {=IFERROR(INDEX('Monthly_Cohort_&_Matrix'!$C:$N,(ROW()-17)*2+2,COLUMN()+ROW()-19),"")} | G27: {=IFERROR(INDEX('Monthly_Cohort_&_Matrix'!$C:$N,(ROW()-17)*2+2,COLUMN()+ROW()-19),"")} | H27: {=IFERROR(INDEX('Monthly_Cohort_&_Matrix'!$C:$N,(ROW()-17)*2+2,COLUMN()+ROW()-19),"")} | I27: {=IFERROR(INDEX('Monthly_Cohort_&_Matrix'!$C:$N,(ROW()-17)*2+2,COLUMN()+ROW()-19),"")} | J27: {=IFERROR(INDEX('Monthly_Cohort_&_Matrix'!$C:$N,(ROW()-17)*2+2,COLUMN()+ROW()-19),"")} | ... N27: {=IFERROR(INDEX('Monthly_Cohort_&_Matrix'!$C:$N,(ROW()-17)*2+2,COLUMN()+ROW()-19),"")}
A28: 44986 | B28: 2727451.8 | C28: {=IFERROR(INDEX('Monthly_Cohort_&_Matrix'!$C:$N,(ROW()-17)*2+2,COLUMN()+ROW()-19),"")} -> 2727451.8 | D28: {=IFERROR(INDEX('Monthly_Cohort_&_Matrix'!$C:$N,(ROW()-17)*2+2,COLUMN()+ROW()-19),"")} | E28: {=IFERROR(INDEX('Monthly_Cohort_&_Matrix'!$C:$N,(ROW()-17)*2+2,COLUMN()+ROW()-19),"")} | F28: {=IFERROR(INDEX('Monthly_Cohort_&_Matrix'!$C:$N,(ROW()-17)*2+2,COLUMN()+ROW()-19),"")} | G28: {=IFERROR(INDEX('Monthly_Cohort_&_Matrix'!$C:$N,(ROW()-17)*2+2,COLUMN()+ROW()-19),"")} | H28: {=IFERROR(INDEX('Monthly_Cohort_&_Matrix'!$C:$N,(ROW()-17)*2+2,COLUMN()+ROW()-19),"")} | I28: {=IFERROR(INDEX('Monthly_Cohort_&_Matrix'!$C:$N,(ROW()-17)*2+2,COLUMN()+ROW()-19),"")} | J28: {=IFERROR(INDEX('Monthly_Cohort_&_Matrix'!$C:$N,(ROW()-17)*2+2,COLUMN()+ROW()-19),"")} | ... N28: {=IFERROR(INDEX('Monthly_Cohort_&_Matrix'!$C:$N,(ROW()-17)*2+2,COLUMN()+ROW()-19),"")}

Sheet Monthly_Retention_Trend
A1: Reg. Month | B1: New Users | C1: M0 | D1: M1 | E1: M2 | F1: M3 | G1: M4 | H1: M5 | I1: M6 | J1: M7 | K1: M8 | L1: M9 | M1: M10 | N1: M11
A2: 44652 | B2: {=TRANSPOSE('Monthly_Cohort_&_Matrix'!C30:N30)} -> 11871 | C2: {=IFERROR(IFERROR(INDEX('Monthly_Cohort_&_Matrix'!$C:$N,(ROW()-2)*2+3,COLUMN()+ROW()-4),"")/$B2,"")} -> 1 | D2: {=IFERROR(IFERROR(INDEX('Monthly_Cohort_&_Matrix'!$C:$N,(ROW()-2)*2+3,COLUMN()+ROW()-4),"")/$B2,"")} -> 0.11827142 | E2: {=IFERROR(IFERROR(INDEX('Monthly_Cohort_&_Matrix'!$C:$N,(ROW()-2)*2+3,COLUMN()+ROW()-4),"")/$B2,"")} -> 0.054165614 | F2: {=IFERROR(IFERROR(INDEX('Monthly_Cohort_&_Matrix'!$C:$N,(ROW()-2)*2+3,COLUMN()+ROW()-4),"")/$B2,"")} -> 0.044225423 | G2: {=IFERROR(IFERROR(INDEX('Monthly_Cohort_&_Matrix'!$C:$N,(ROW()-2)*2+3,COLUMN()+ROW()-4),"")/$B2,"")} -> 0.028725465 | H2: {=IFERROR(IFERROR(INDEX('Monthly_Cohort_&_Matrix'!$C:$N,(ROW()-2)*2+3,COLUMN()+ROW()-4),"")/$B2,"")} -> 0.027714599 | I2: {=IFERROR(IFERROR(INDEX('Monthly_Cohort_&_Matrix'!$C:$N,(ROW()-2)*2+3,COLUMN()+ROW()-4),"")/$B2,"")} -> 0.02763036 | J2: {=IFERROR(IFERROR(INDEX('Monthly_Cohort_&_Matrix'!$C:$N,(ROW()-2)*2+3,COLUMN()+ROW()-4),"")/$B2,"")} -> 0.020385814 | ... N2: {=IFERROR(IFERROR(INDEX('Monthly_Cohort_&_Matrix'!$C:$N,(ROW()-2)*2+3,COLUMN()+ROW()-4),"")/$B2,"")} -> 0.01381518
A3: 44682 | B3: 15998 | C3: {=IFERROR(IFERROR(INDEX('Monthly_Cohort_&_Matrix'!$C:$N,(ROW()-2)*2+3,COLUMN()+ROW()-4),"")/$B3,"")} -> 1 | D3: {=IFERROR(IFERROR(INDEX('Monthly_Cohort_&_Matrix'!$C:$N,(ROW()-2)*2+3,COLUMN()+ROW()-4),"")/$B3,"")} -> 0.12026503 | E3: {=IFERROR(IFERROR(INDEX('Monthly_Cohort_&_Matrix'!$C:$N,(ROW()-2)*2+3,COLUMN()+ROW()-4),"")/$B3,"")} -> 0.057257157 | F3: {=IFERROR(IFERROR(INDEX('Monthly_Cohort_&_Matrix'!$C:$N,(ROW()-2)*2+3,COLUMN()+ROW()-4),"")/$B3,"")} -> 0.03831729 | G3: {=IFERROR(IFERROR(INDEX('Monthly_Cohort_&_Matrix'!$C:$N,(ROW()-2)*2+3,COLUMN()+ROW()-4),"")/$B3,"")} -> 0.030253782 | H3: {=IFERROR(IFERROR(INDEX('Monthly_Cohort_&_Matrix'!$C:$N,(ROW()-2)*2+3,COLUMN()+ROW()-4),"")/$B3,"")} -> 0.029691211 | I3: {=IFERROR(IFERROR(INDEX('Monthly_Cohort_&_Matrix'!$C:$N,(ROW()-2)*2+3,COLUMN()+ROW()-4),"")/$B3,"")} -> 0.022377797 | J3: {=IFERROR(IFERROR(INDEX('Monthly_Cohort_&_Matrix'!$C:$N,(ROW()-2)*2+3,COLUMN()+ROW()-4),"")/$B3,"")} -> 0.021002625 | ... N3: {=IFERROR(IFERROR(INDEX('Monthly_Cohort_&_Matrix'!$C:$N,(ROW()-2)*2+3,COLUMN()+ROW()-4),"")/$B3,"")}
A4: 44713 | B4: 19147 | C4: {=IFERROR(IFERROR(INDEX('Monthly_Cohort_&_Matrix'!$C:$N,(ROW()-2)*2+3,COLUMN()+ROW()-4),"")/$B4,"")} -> 1 | D4: {=IFERROR(IFERROR(INDEX('Monthly_Cohort_&_Matrix'!$C:$N,(ROW()-2)*2+3,COLUMN()+ROW()-4),"")/$B4,"")} -> 0.11390818 | E4: {=IFERROR(IFERROR(INDEX('Monthly_Cohort_&_Matrix'!$C:$N,(ROW()-2)*2+3,COLUMN()+ROW()-4),"")/$B4,"")} -> 0.03619366 | F4: {=IFERROR(IFERROR(INDEX('Monthly_Cohort_&_Matrix'!$C:$N,(ROW()-2)*2+3,COLUMN()+ROW()-4),"")/$B4,"")} -> 0.030814227 | G4: {=IFERROR(IFERROR(INDEX('Monthly_Cohort_&_Matrix'!$C:$N,(ROW()-2)*2+3,COLUMN()+ROW()-4),"")/$B4,"")} -> 0.026479344 | H4: {=IFERROR(IFERROR(INDEX('Monthly_Cohort_&_Matrix'!$C:$N,(ROW()-2)*2+3,COLUMN()+ROW()-4),"")/$B4,"")} -> 0.017391759 | I4: {=IFERROR(IFERROR(INDEX('Monthly_Cohort_&_Matrix'!$C:$N,(ROW()-2)*2+3,COLUMN()+ROW()-4),"")/$B4,"")} -> 0.015824933 | J4: {=IFERROR(IFERROR(INDEX('Monthly_Cohort_&_Matrix'!$C:$N,(ROW()-2)*2+3,COLUMN()+ROW()-4),"")/$B4,"")} -> 0.013265786 | ... N4: {=IFERROR(IFERROR(INDEX('Monthly_Cohort_&_Matrix'!$C:$N,(ROW()-2)*2+3,COLUMN()+ROW()-4),"")/$B4,"")}
A5: 44743 | B5: 19360 | C5: {=IFERROR(IFERROR(INDEX('Monthly_Cohort_&_Matrix'!$C:$N,(ROW()-2)*2+3,COLUMN()+ROW()-4),"")/$B5,"")} -> 1 | D5: {=IFERROR(IFERROR(INDEX('Monthly_Cohort_&_Matrix'!$C:$N,(ROW()-2)*2+3,COLUMN()+ROW()-4),"")/$B5,"")} -> 0.087190083 | E5: {=IFERROR(IFERROR(INDEX('Monthly_Cohort_&_Matrix'!$C:$N,(ROW()-2)*2+3,COLUMN()+ROW()-4),"")/$B5,"")} -> 0.042923554 | F5: {=IFERROR(IFERROR(INDEX('Monthly_Cohort_&_Matrix'!$C:$N,(ROW()-2)*2+3,COLUMN()+ROW()-4),"")/$B5,"")} -> 0.032644628 | G5: {=IFERROR(IFERROR(INDEX('Monthly_Cohort_&_Matrix'!$C:$N,(ROW()-2)*2+3,COLUMN()+ROW()-4),"")/$B5,"")} -> 0.020919421 | H5: {=IFERROR(IFERROR(INDEX('Monthly_Cohort_&_Matrix'!$C:$N,(ROW()-2)*2+3,COLUMN()+ROW()-4),"")/$B5,"")} -> 0.018440083 | I5: {=IFERROR(IFERROR(INDEX('Monthly_Cohort_&_Matrix'!$C:$N,(ROW()-2)*2+3,COLUMN()+ROW()-4),"")/$B5,"")} -> 0.01678719 | J5: {=IFERROR(IFERROR(INDEX('Monthly_Cohort_&_Matrix'!$C:$N,(ROW()-2)*2+3,COLUMN()+ROW()-4),"")/$B5,"")} -> 0.014772727 | ... N5: {=IFERROR(IFERROR(INDEX('Monthly_Cohort_&_Matrix'!$C:$N,(ROW()-2)*2+3,COLUMN()+ROW()-4),"")/$B5,"")}
A6: 44774 | B6: 18585 | C6: {=IFERROR(IFERROR(INDEX('Monthly_Cohort_&_Matrix'!$C:$N,(ROW()-2)*2+3,COLUMN()+ROW()-4),"")/$B6,"")} -> 1 | D6: {=IFERROR(IFERROR(INDEX('Monthly_Cohort_&_Matrix'!$C:$N,(ROW()-2)*2+3,COLUMN()+ROW()-4),"")/$B6,"")} -> 0.080495023 | E6: {=IFERROR(IFERROR(INDEX('Monthly_Cohort_&_Matrix'!$C:$N,(ROW()-2)*2+3,COLUMN()+ROW()-4),"")/$B6,"")} -> 0.039063761 | F6: {=IFERROR(IFERROR(INDEX('Monthly_Cohort_&_Matrix'!$C:$N,(ROW()-2)*2+3,COLUMN()+ROW()-4),"")/$B6,"")} -> 0.020823245 | G6: {=IFERROR(IFERROR(INDEX('Monthly_Cohort_&_Matrix'!$C:$N,(ROW()-2)*2+3,COLUMN()+ROW()-4),"")/$B6,"")} -> 0.019693301 | H6: {=IFERROR(IFERROR(INDEX('Monthly_Cohort_&_Matrix'!$C:$N,(ROW()-2)*2+3,COLUMN()+ROW()-4),"")/$B6,"")} -> 0.015442561 | I6: {=IFERROR(IFERROR(INDEX('Monthly_Cohort_&_Matrix'!$C:$N,(ROW()-2)*2+3,COLUMN()+ROW()-4),"")/$B6,"")} -> 0.01275222 | J6: {=IFERROR(IFERROR(INDEX('Monthly_Cohort_&_Matrix'!$C:$N,(ROW()-2)*2+3,COLUMN()+ROW()-4),"")/$B6,"")} -> 0.01070756 | ... N6: {=IFERROR(IFERROR(INDEX('Monthly_Cohort_&_Matrix'!$C:$N,(ROW()-2)*2+3,COLUMN()+ROW()-4),"")/$B6,"")}
A7: 44805 | B7: 13772 | C7: {=IFERROR(IFERROR(INDEX('Monthly_Cohort_&_Matrix'!$C:$N,(ROW()-2)*2+3,COLUMN()+ROW()-4),"")/$B7,"")} -> 1 | D7: {=IFERROR(IFERROR(INDEX('Monthly_Cohort_&_Matrix'!$C:$N,(ROW()-2)*2+3,COLUMN()+ROW()-4),"")/$B7,"")} -> 0.079726982 | E7: {=IFERROR(IFERROR(INDEX('Monthly_Cohort_&_Matrix'!$C:$N,(ROW()-2)*2+3,COLUMN()+ROW()-4),"")/$B7,"")} -> 0.032747604 | F7: {=IFERROR(IFERROR(INDEX('Monthly_Cohort_&_Matrix'!$C:$N,(ROW()-2)*2+3,COLUMN()+ROW()-4),"")/$B7,"")} -> 0.024397328 | G7: {=IFERROR(IFERROR(INDEX('Monthly_Cohort_&_Matrix'!$C:$N,(ROW()-2)*2+3,COLUMN()+ROW()-4),"")/$B7,"")} -> 0.01924194 | H7: {=IFERROR(IFERROR(INDEX('Monthly_Cohort_&_Matrix'!$C:$N,(ROW()-2)*2+3,COLUMN()+ROW()-4),"")/$B7,"")} -> 0.015320941 | I7: {=IFERROR(IFERROR(INDEX('Monthly_Cohort_&_Matrix'!$C:$N,(ROW()-2)*2+3,COLUMN()+ROW()-4),"")/$B7,"")} -> 0.012489108 | J7: {=IFERROR(IFERROR(INDEX('Monthly_Cohort_&_Matrix'!$C:$N,(ROW()-2)*2+3,COLUMN()+ROW()-4),"")/$B7,"")} | ... N7: {=IFERROR(IFERROR(INDEX('Monthly_Cohort_&_Matrix'!$C:$N,(ROW()-2)*2+3,COLUMN()+ROW()-4),"")/$B7,"")}
A8: 44835 | B8: 10553 | C8: {=IFERROR(IFERROR(INDEX('Monthly_Cohort_&_Matrix'!$C:$N,(ROW()-2)*2+3,COLUMN()+ROW()-4),"")/$B8,"")} -> 1 | D8: {=IFERROR(IFERROR(INDEX('Monthly_Cohort_&_Matrix'!$C:$N,(ROW()-2)*2+3,COLUMN()+ROW()-4),"")/$B8,"")} -> 0.090211314 | E8: {=IFERROR(IFERROR(INDEX('Monthly_Cohort_&_Matrix'!$C:$N,(ROW()-2)*2+3,COLUMN()+ROW()-4),"")/$B8,"")} -> 0.042547143 | F8: {=IFERROR(IFERROR(INDEX('Monthly_Cohort_&_Matrix'!$C:$N,(ROW()-2)*2+3,COLUMN()+ROW()-4),"")/$B8,"")} -> 0.022173789 | G8: {=IFERROR(IFERROR(INDEX('Monthly_Cohort_&_Matrix'!$C:$N,(ROW()-2)*2+3,COLUMN()+ROW()-4),"")/$B8,"")} -> 0.01753056 | H8: {=IFERROR(IFERROR(INDEX('Monthly_Cohort_&_Matrix'!$C:$N,(ROW()-2)*2+3,COLUMN()+ROW()-4),"")/$B8,"")} -> 0.013929688 | I8: {=IFERROR(IFERROR(INDEX('Monthly_Cohort_&_Matrix'!$C:$N,(ROW()-2)*2+3,COLUMN()+ROW()-4),"")/$B8,"")} | J8: {=IFERROR(IFERROR(INDEX('Monthly_Cohort_&_Matrix'!$C:$N,(ROW()-2)*2+3,COLUMN()+ROW()-4),"")/$B8,"")} | ... N8: {=IFERROR(IFERROR(INDEX('Monthly_Cohort_&_Matrix'!$C:$N,(ROW()-2)*2+3,COLUMN()+ROW()-4),"")/$B8,"")}
A9: 44866 | B9: 12935 | C9: {=IFERROR(IFERROR(INDEX('Monthly_Cohort_&_Matrix'!$C:$N,(ROW()-2)*2+3,COLUMN()+ROW()-4),"")/$B9,"")} -> 1 | D9: {=IFERROR(IFERROR(INDEX('Monthly_Cohort_&_Matrix'!$C:$N,(ROW()-2)*2+3,COLUMN()+ROW()-4),"")/$B9,"")} -> 0.094472362 | E9: {=IFERROR(IFERROR(INDEX('Monthly_Cohort_&_Matrix'!$C:$N,(ROW()-2)*2+3,COLUMN()+ROW()-4),"")/$B9,"")} -> 0.032083494 | F9: {=IFERROR(IFERROR(INDEX('Monthly_Cohort_&_Matrix'!$C:$N,(ROW()-2)*2+3,COLUMN()+ROW()-4),"")/$B9,"")} -> 0.021105528 | G9: {=IFERROR(IFERROR(INDEX('Monthly_Cohort_&_Matrix'!$C:$N,(ROW()-2)*2+3,COLUMN()+ROW()-4),"")/$B9,"")} -> 0.017471975 | H9: {=IFERROR(IFERROR(INDEX('Monthly_Cohort_&_Matrix'!$C:$N,(ROW()-2)*2+3,COLUMN()+ROW()-4),"")/$B9,"")} | I9: {=IFERROR(IFERROR(INDEX('Monthly_Cohort_&_Matrix'!$C:$N,(ROW()-2)*2+3,COLUMN()+ROW()-4),"")/$B9,"")} | J9: {=IFERROR(IFERROR(INDEX('Monthly_Cohort_&_Matrix'!$C:$N,(ROW()-2)*2+3,COLUMN()+ROW()-4),"")/$B9,"")} | ... N9: {=IFERROR(IFERROR(INDEX('Monthly_Cohort_&_Matrix'!$C:$N,(ROW()-2)*2+3,COLUMN()+ROW()-4),"")/$B9,"")}
A10: 44896 | B10: 10997 | C10: {=IFERROR(IFERROR(INDEX('Monthly_Cohort_&_Matrix'!$C:$N,(ROW()-2)*2+3,COLUMN()+ROW()-4),"")/$B10,"")} -> 1 | D10: {=IFERROR(IFERROR(INDEX('Monthly_Cohort_&_Matrix'!$C:$N,(ROW()-2)*2+3,COLUMN()+ROW()-4),"")/$B10,"")} -> 0.078203146 | E10: {=IFERROR(IFERROR(INDEX('Monthly_Cohort_&_Matrix'!$C:$N,(ROW()-2)*2+3,COLUMN()+ROW()-4),"")/$B10,"")} -> 0.033918341 | F10: {=IFERROR(IFERROR(INDEX('Monthly_Cohort_&_Matrix'!$C:$N,(ROW()-2)*2+3,COLUMN()+ROW()-4),"")/$B10,"")} -> 0.025097754 | G10: {=IFERROR(IFERROR(INDEX('Monthly_Cohort_&_Matrix'!$C:$N,(ROW()-2)*2+3,COLUMN()+ROW()-4),"")/$B10,"")} | H10: {=IFERROR(IFERROR(INDEX('Monthly_Cohort_&_Matrix'!$C:$N,(ROW()-2)*2+3,COLUMN()+ROW()-4),"")/$B10,"")} | I10: {=IFERROR(IFERROR(INDEX('Monthly_Cohort_&_Matrix'!$C:$N,(ROW()-2)*2+3,COLUMN()+ROW()-4),"")/$B10,"")} | J10: {=IFERROR(IFERROR(INDEX('Monthly_Cohort_&_Matrix'!$C:$N,(ROW()-2)*2+3,COLUMN()+ROW()-4),"")/$B10,"")} | ... N10: {=IFERROR(IFERROR(INDEX('Monthly_Cohort_&_Matrix'!$C:$N,(ROW()-2)*2+3,COLUMN()+ROW()-4),"")/$B10,"")}
A11: 44927 | B11: 11697 | C11: {=IFERROR(IFERROR(INDEX('Monthly_Cohort_&_Matrix'!$C:$N,(ROW()-2)*2+3,COLUMN()+ROW()-4),"")/$B11,"")} -> 1 | D11: {=IFERROR(IFERROR(INDEX('Monthly_Cohort_&_Matrix'!$C:$N,(ROW()-2)*2+3,COLUMN()+ROW()-4),"")/$B11,"")} -> 0.085150038 | E11: {=IFERROR(IFERROR(INDEX('Monthly_Cohort_&_Matrix'!$C:$N,(ROW()-2)*2+3,COLUMN()+ROW()-4),"")/$B11,"")} -> 0.038813371 | F11: {=IFERROR(IFERROR(INDEX('Monthly_Cohort_&_Matrix'!$C:$N,(ROW()-2)*2+3,COLUMN()+ROW()-4),"")/$B11,"")} | G11: {=IFERROR(IFERROR(INDEX('Monthly_Cohort_&_Matrix'!$C:$N,(ROW()-2)*2+3,COLUMN()+ROW()-4),"")/$B11,"")} | H11: {=IFERROR(IFERROR(INDEX('Monthly_Cohort_&_Matrix'!$C:$N,(ROW()-2)*2+3,COLUMN()+ROW()-4),"")/$B11,"")} | I11: {=IFERROR(IFERROR(INDEX('Monthly_Cohort_&_Matrix'!$C:$N,(ROW()-2)*2+3,COLUMN()+ROW()-4),"")/$B11,"")} | J11: {=IFERROR(IFERROR(INDEX('Monthly_Cohort_&_Matrix'!$C:$N,(ROW()-2)*2+3,COLUMN()+ROW()-4),"")/$B11,"")} | ... N11: {=IFERROR(IFERROR(INDEX('Monthly_Cohort_&_Matrix'!$C:$N,(ROW()-2)*2+3,COLUMN()+ROW()-4),"")/$B11,"")}
A12: 44958 | B12: 11724 | C12: {=IFERROR(IFERROR(INDEX('Monthly_Cohort_&_Matrix'!$C:$N,(ROW()-2)*2+3,COLUMN()+ROW()-4),"")/$B12,"")} -> 1 | D12: {=IFERROR(IFERROR(INDEX('Monthly_Cohort_&_Matrix'!$C:$N,(ROW()-2)*2+3,COLUMN()+ROW()-4),"")/$B12,"")} -> 0.072927329 | E12: {=IFERROR(IFERROR(INDEX('Monthly_Cohort_&_Matrix'!$C:$N,(ROW()-2)*2+3,COLUMN()+ROW()-4),"")/$B12,"")} | F12: {=IFERROR(IFERROR(INDEX('Monthly_Cohort_&_Matrix'!$C:$N,(ROW()-2)*2+3,COLUMN()+ROW()-4),"")/$B12,"")} | G12: {=IFERROR(IFERROR(INDEX('Monthly_Cohort_&_Matrix'!$C:$N,(ROW()-2)*2+3,COLUMN()+ROW()-4),"")/$B12,"")} | H12: {=IFERROR(IFERROR(INDEX('Monthly_Cohort_&_Matrix'!$C:$N,(ROW()-2)*2+3,COLUMN()+ROW()-4),"")/$B12,"")} | I12: {=IFERROR(IFERROR(INDEX('Monthly_Cohort_&_Matrix'!$C:$N,(ROW()-2)*2+3,COLUMN()+ROW()-4),"")/$B12,"")} | J12: {=IFERROR(IFERROR(INDEX('Monthly_Cohort_&_Matrix'!$C:$N,(ROW()-2)*2+3,COLUMN()+ROW()-4),"")/$B12,"")} | ... N12: {=IFERROR(IFERROR(INDEX('Monthly_Cohort_&_Matrix'!$C:$N,(ROW()-2)*2+3,COLUMN()+ROW()-4),"")/$B12,"")}
A13: 44986 | B13: 14383 | C13: {=IFERROR(IFERROR(INDEX('Monthly_Cohort_&_Matrix'!$C:$N,(ROW()-2)*2+3,COLUMN()+ROW()-4),"")/$B13,"")} -> 1 | D13: {=IFERROR(IFERROR(INDEX('Monthly_Cohort_&_Matrix'!$C:$N,(ROW()-2)*2+3,COLUMN()+ROW()-4),"")/$B13,"")} | E13: {=IFERROR(IFERROR(INDEX('Monthly_Cohort_&_Matrix'!$C:$N,(ROW()-2)*2+3,COLUMN()+ROW()-4),"")/$B13,"")} | F13: {=IFERROR(IFERROR(INDEX('Monthly_Cohort_&_Matrix'!$C:$N,(ROW()-2)*2+3,COLUMN()+ROW()-4),"")/$B13,"")} | G13: {=IFERROR(IFERROR(INDEX('Monthly_Cohort_&_Matrix'!$C:$N,(ROW()-2)*2+3,COLUMN()+ROW()-4),"")/$B13,"")} | H13: {=IFERROR(IFERROR(INDEX('Monthly_Cohort_&_Matrix'!$C:$N,(ROW()-2)*2+3,COLUMN()+ROW()-4),"")/$B13,"")} | I13: {=IFERROR(IFERROR(INDEX('Monthly_Cohort_&_Matrix'!$C:$N,(ROW()-2)*2+3,COLUMN()+ROW()-4),"")/$B13,"")} | J13: {=IFERROR(IFERROR(INDEX('Monthly_Cohort_&_Matrix'!$C:$N,(ROW()-2)*2+3,COLUMN()+ROW()-4),"")/$B13,"")} | ... N13: {=IFERROR(IFERROR(INDEX('Monthly_Cohort_&_Matrix'!$C:$N,(ROW()-2)*2+3,COLUMN()+ROW()-4),"")/$B13,"")}
A16: Reg. Month | B16: New Users Rev. | C16: M0 | D16: M1 | E16: M2 | F16: M3 | G16: M4 | H16: M5 | I16: M6 | J16: M7 | K16: M8 | L16: M9 | M16: M10 | N16: M11
A17: 44652 | B17: {=TRANSPOSE('Monthly_Cohort_&_Matrix'!C34:N34)} -> 3470489 | C17: {=IFERROR(IFERROR(INDEX('Monthly_Cohort_&_Matrix'!$C:$N,(ROW()-17)*2+2,COLUMN()+ROW()-19),"")/$B17,"")} -> 1 | D17: {=IFERROR(IFERROR(INDEX('Monthly_Cohort_&_Matrix'!$C:$N,(ROW()-17)*2+2,COLUMN()+ROW()-19),"")/$B17,"")} -> 1.3058234 | E17: {=IFERROR(IFERROR(INDEX('Monthly_Cohort_&_Matrix'!$C:$N,(ROW()-17)*2+2,COLUMN()+ROW()-19),"")/$B17,"")} -> 0.58090508 | F17: {=IFERROR(IFERROR(INDEX('Monthly_Cohort_&_Matrix'!$C:$N,(ROW()-17)*2+2,COLUMN()+ROW()-19),"")/$B17,"")} -> 0.42644201 | G17: {=IFERROR(IFERROR(INDEX('Monthly_Cohort_&_Matrix'!$C:$N,(ROW()-17)*2+2,COLUMN()+ROW()-19),"")/$B17,"")} -> 0.4335586 | H17: {=IFERROR(IFERROR(INDEX('Monthly_Cohort_&_Matrix'!$C:$N,(ROW()-17)*2+2,COLUMN()+ROW()-19),"")/$B17,"")} -> 0.46427048 | I17: {=IFERROR(IFERROR(INDEX('Monthly_Cohort_&_Matrix'!$C:$N,(ROW()-17)*2+2,COLUMN()+ROW()-19),"")/$B17,"")} -> 0.43859431 | J17: {=IFERROR(IFERROR(INDEX('Monthly_Cohort_&_Matrix'!$C:$N,(ROW()-17)*2+2,COLUMN()+ROW()-19),"")/$B17,"")} -> 0.4124031 | ... N17: {=IFERROR(IFERROR(INDEX('Monthly_Cohort_&_Matrix'!$C:$N,(ROW()-17)*2+2,COLUMN()+ROW()-19),"")/$B17,"")} -> 0.46483272
A18: 44682 | B18: 5119928.2 | C18: {=IFERROR(IFERROR(INDEX('Monthly_Cohort_&_Matrix'!$C:$N,(ROW()-17)*2+2,COLUMN()+ROW()-19),"")/$B18,"")} -> 1 | D18: {=IFERROR(IFERROR(INDEX('Monthly_Cohort_&_Matrix'!$C:$N,(ROW()-17)*2+2,COLUMN()+ROW()-19),"")/$B18,"")} -> 0.63511232 | E18: {=IFERROR(IFERROR(INDEX('Monthly_Cohort_&_Matrix'!$C:$N,(ROW()-17)*2+2,COLUMN()+ROW()-19),"")/$B18,"")} -> 0.4110926 | F18: {=IFERROR(IFERROR(INDEX('Monthly_Cohort_&_Matrix'!$C:$N,(ROW()-17)*2+2,COLUMN()+ROW()-19),"")/$B18,"")} -> 0.35896635 | G18: {=IFERROR(IFERROR(INDEX('Monthly_Cohort_&_Matrix'!$C:$N,(ROW()-17)*2+2,COLUMN()+ROW()-19),"")/$B18,"")} -> 0.22250338 | H18: {=IFERROR(IFERROR(INDEX('Monthly_Cohort_&_Matrix'!$C:$N,(ROW()-17)*2+2,COLUMN()+ROW()-19),"")/$B18,"")} -> 0.12556742 | I18: {=IFERROR(IFERROR(INDEX('Monthly_Cohort_&_Matrix'!$C:$N,(ROW()-17)*2+2,COLUMN()+ROW()-19),"")/$B18,"")} -> 0.14628463 | J18: {=IFERROR(IFERROR(INDEX('Monthly_Cohort_&_Matrix'!$C:$N,(ROW()-17)*2+2,COLUMN()+ROW()-19),"")/$B18,"")} -> 0.21688415 | ... N18: {=IFERROR(IFERROR(INDEX('Monthly_Cohort_&_Matrix'!$C:$N,(ROW()-17)*2+2,COLUMN()+ROW()-19),"")/$B18,"")}
A19: 44713 | B19: 3815355.3 | C19: {=IFERROR(IFERROR(INDEX('Monthly_Cohort_&_Matrix'!$C:$N,(ROW()-17)*2+2,COLUMN()+ROW()-19),"")/$B19,"")} -> 1 | D19: {=IFERROR(IFERROR(INDEX('Monthly_Cohort_&_Matrix'!$C:$N,(ROW()-17)*2+2,COLUMN()+ROW()-19),"")/$B19,"")} -> 0.67558958 | E19: {=IFERROR(IFERROR(INDEX('Monthly_Cohort_&_Matrix'!$C:$N,(ROW()-17)*2+2,COLUMN()+ROW()-19),"")/$B19,"")} -> 0.37570429 | F19: {=IFERROR(IFERROR(INDEX('Monthly_Cohort_&_Matrix'!$C:$N,(ROW()-17)*2+2,COLUMN()+ROW()-19),"")/$B19,"")} -> 0.36442773 | G19: {=IFERROR(IFERROR(INDEX('Monthly_Cohort_&_Matrix'!$C:$N,(ROW()-17)*2+2,COLUMN()+ROW()-19),"")/$B19,"")} -> 0.35350919 | H19: {=IFERROR(IFERROR(INDEX('Monthly_Cohort_&_Matrix'!$C:$N,(ROW()-17)*2+2,COLUMN()+ROW()-19),"")/$B19,"")} -> 0.22039372 | I19: {=IFERROR(IFERROR(INDEX('Monthly_Cohort_&_Matrix'!$C:$N,(ROW()-17)*2+2,COLUMN()+ROW()-19),"")/$B19,"")} -> 0.1963635 | J19: {=IFERROR(IFERROR(INDEX('Monthly_Cohort_&_Matrix'!$C:$N,(ROW()-17)*2+2,COLUMN()+ROW()-19),"")/$B19,"")} -> 0.17392315 | ... N19: {=IFERROR(IFERROR(INDEX('Monthly_Cohort_&_Matrix'!$C:$N,(ROW()-17)*2+2,COLUMN()+ROW()-19),"")/$B19,"")}
A20: 44743 | B20: 4547888.8 | C20: {=IFERROR(IFERROR(INDEX('Monthly_Cohort_&_Matrix'!$C:$N,(ROW()-17)*2+2,COLUMN()+ROW()-19),"")/$B20,"")} -> 1 | D20: {=IFERROR(IFERROR(INDEX('Monthly_Cohort_&_Matrix'!$C:$N,(ROW()-17)*2+2,COLUMN()+ROW()-19),"")/$B20,"")} -> 0.91616808 | E20: {=IFERROR(IFERROR(INDEX('Monthly_Cohort_&_Matrix'!$C:$N,(ROW()-17)*2+2,COLUMN()+ROW()-19),"")/$B20,"")} -> 0.52827866 | F20: {=IFERROR(IFERROR(INDEX('Monthly_Cohort_&_Matrix'!$C:$N,(ROW()-17)*2+2,COLUMN()+ROW()-19),"")/$B20,"")} -> 0.39840725 | G20: {=IFERROR(IFERROR(INDEX('Monthly_Cohort_&_Matrix'!$C:$N,(ROW()-17)*2+2,COLUMN()+ROW()-19),"")/$B20,"")} -> 0.58346362 | H20: {=IFERROR(IFERROR(INDEX('Monthly_Cohort_&_Matrix'!$C:$N,(ROW()-17)*2+2,COLUMN()+ROW()-19),"")/$B20,"")} -> 0.68718319 | I20: {=IFERROR(IFERROR(INDEX('Monthly_Cohort_&_Matrix'!$C:$N,(ROW()-17)*2+2,COLUMN()+ROW()-19),"")/$B20,"")} -> 0.53564269 | J20: {=IFERROR(IFERROR(INDEX('Monthly_Cohort_&_Matrix'!$C:$N,(ROW()-17)*2+2,COLUMN()+ROW()-19),"")/$B20,"")} -> 0.34282854 | ... N20: {=IFERROR(IFERROR(INDEX('Monthly_Cohort_&_Matrix'!$C:$N,(ROW()-17)*2+2,COLUMN()+ROW()-19),"")/$B20,"")}
A21: 44774 | B21: 2906573.5 | C21: {=IFERROR(IFERROR(INDEX('Monthly_Cohort_&_Matrix'!$C:$N,(ROW()-17)*2+2,COLUMN()+ROW()-19),"")/$B21,"")} -> 1 | D21: {=IFERROR(IFERROR(INDEX('Monthly_Cohort_&_Matrix'!$C:$N,(ROW()-17)*2+2,COLUMN()+ROW()-19),"")/$B21,"")} -> 0.61035344 | E21: {=IFERROR(IFERROR(INDEX('Monthly_Cohort_&_Matrix'!$C:$N,(ROW()-17)*2+2,COLUMN()+ROW()-19),"")/$B21,"")} -> 0.48272054 | F21: {=IFERROR(IFERROR(INDEX('Monthly_Cohort_&_Matrix'!$C:$N,(ROW()-17)*2+2,COLUMN()+ROW()-19),"")/$B21,"")} -> 0.3831499 | G21: {=IFERROR(IFERROR(INDEX('Monthly_Cohort_&_Matrix'!$C:$N,(ROW()-17)*2+2,COLUMN()+ROW()-19),"")/$B21,"")} -> 0.42579247 | H21: {=IFERROR(IFERROR(INDEX('Monthly_Cohort_&_Matrix'!$C:$N,(ROW()-17)*2+2,COLUMN()+ROW()-19),"")/$B21,"")} -> 0.52926106 | I21: {=IFERROR(IFERROR(INDEX('Monthly_Cohort_&_Matrix'!$C:$N,(ROW()-17)*2+2,COLUMN()+ROW()-19),"")/$B21,"")} -> 0.24276648 | J21: {=IFERROR(IFERROR(INDEX('Monthly_Cohort_&_Matrix'!$C:$N,(ROW()-17)*2+2,COLUMN()+ROW()-19),"")/$B21,"")} -> 0.31863901 | ... N21: {=IFERROR(IFERROR(INDEX('Monthly_Cohort_&_Matrix'!$C:$N,(ROW()-17)*2+2,COLUMN()+ROW()-19),"")/$B21,"")}
A22: 44805 | B22: 2178295.9 | C22: {=IFERROR(IFERROR(INDEX('Monthly_Cohort_&_Matrix'!$C:$N,(ROW()-17)*2+2,COLUMN()+ROW()-19),"")/$B22,"")} -> 1 | D22: {=IFERROR(IFERROR(INDEX('Monthly_Cohort_&_Matrix'!$C:$N,(ROW()-17)*2+2,COLUMN()+ROW()-19),"")/$B22,"")} -> 0.60572697 | E22: {=IFERROR(IFERROR(INDEX('Monthly_Cohort_&_Matrix'!$C:$N,(ROW()-17)*2+2,COLUMN()+ROW()-19),"")/$B22,"")} -> 0.43034583 | F22: {=IFERROR(IFERROR(INDEX('Monthly_Cohort_&_Matrix'!$C:$N,(ROW()-17)*2+2,COLUMN()+ROW()-19),"")/$B22,"")} -> 0.35806735 | G22: {=IFERROR(IFERROR(INDEX('Monthly_Cohort_&_Matrix'!$C:$N,(ROW()-17)*2+2,COLUMN()+ROW()-19),"")/$B22,"")} -> 0.49299822 | H22: {=IFERROR(IFERROR(INDEX('Monthly_Cohort_&_Matrix'!$C:$N,(ROW()-17)*2+2,COLUMN()+ROW()-19),"")/$B22,"")} -> 0.23830148 | I22: {=IFERROR(IFERROR(INDEX('Monthly_Cohort_&_Matrix'!$C:$N,(ROW()-17)*2+2,COLUMN()+ROW()-19),"")/$B22,"")} -> 0.19104229 | J22: {=IFERROR(IFERROR(INDEX('Monthly_Cohort_&_Matrix'!$C:$N,(ROW()-17)*2+2,COLUMN()+ROW()-19),"")/$B22,"")} | ... N22: {=IFERROR(IFERROR(INDEX('Monthly_Cohort_&_Matrix'!$C:$N,(ROW()-17)*2+2,COLUMN()+ROW()-19),"")/$B22,"")}
A23: 44835 | B23: 2894310.4 | C23: {=IFERROR(IFERROR(INDEX('Monthly_Cohort_&_Matrix'!$C:$N,(ROW()-17)*2+2,COLUMN()+ROW()-19),"")/$B23,"")} -> 1 | D23: {=IFERROR(IFERROR(INDEX('Monthly_Cohort_&_Matrix'!$C:$N,(ROW()-17)*2+2,COLUMN()+ROW()-19),"")/$B23,"")} -> 0.83703796 | E23: {=IFERROR(IFERROR(INDEX('Monthly_Cohort_&_Matrix'!$C:$N,(ROW()-17)*2+2,COLUMN()+ROW()-19),"")/$B23,"")} -> 0.38137119 | F23: {=IFERROR(IFERROR(INDEX('Monthly_Cohort_&_Matrix'!$C:$N,(ROW()-17)*2+2,COLUMN()+ROW()-19),"")/$B23,"")} -> 0.28504697 | G23: {=IFERROR(IFERROR(INDEX('Monthly_Cohort_&_Matrix'!$C:$N,(ROW()-17)*2+2,COLUMN()+ROW()-19),"")/$B23,"")} -> 0.2518804 | H23: {=IFERROR(IFERROR(INDEX('Monthly_Cohort_&_Matrix'!$C:$N,(ROW()-17)*2+2,COLUMN()+ROW()-19),"")/$B23,"")} -> 0.36261293 | I23: {=IFERROR(IFERROR(INDEX('Monthly_Cohort_&_Matrix'!$C:$N,(ROW()-17)*2+2,COLUMN()+ROW()-19),"")/$B23,"")} | J23: {=IFERROR(IFERROR(INDEX('Monthly_Cohort_&_Matrix'!$C:$N,(ROW()-17)*2+2,COLUMN()+ROW()-19),"")/$B23,"")} | ... N23: {=IFERROR(IFERROR(INDEX('Monthly_Cohort_&_Matrix'!$C:$N,(ROW()-17)*2+2,COLUMN()+ROW()-19),"")/$B23,"")}
A24: 44866 | B24: 3252521.6 | C24: {=IFERROR(IFERROR(INDEX('Monthly_Cohort_&_Matrix'!$C:$N,(ROW()-17)*2+2,COLUMN()+ROW()-19),"")/$B24,"")} -> 1 | D24: {=IFERROR(IFERROR(INDEX('Monthly_Cohort_&_Matrix'!$C:$N,(ROW()-17)*2+2,COLUMN()+ROW()-19),"")/$B24,"")} -> 0.90766827 | E24: {=IFERROR(IFERROR(INDEX('Monthly_Cohort_&_Matrix'!$C:$N,(ROW()-17)*2+2,COLUMN()+ROW()-19),"")/$B24,"")} -> 0.48639546 | F24: {=IFERROR(IFERROR(INDEX('Monthly_Cohort_&_Matrix'!$C:$N,(ROW()-17)*2+2,COLUMN()+ROW()-19),"")/$B24,"")} -> 0.39884389 | G24: {=IFERROR(IFERROR(INDEX('Monthly_Cohort_&_Matrix'!$C:$N,(ROW()-17)*2+2,COLUMN()+ROW()-19),"")/$B24,"")} -> 0.56536825 | H24: {=IFERROR(IFERROR(INDEX('Monthly_Cohort_&_Matrix'!$C:$N,(ROW()-17)*2+2,COLUMN()+ROW()-19),"")/$B24,"")} | I24: {=IFERROR(IFERROR(INDEX('Monthly_Cohort_&_Matrix'!$C:$N,(ROW()-17)*2+2,COLUMN()+ROW()-19),"")/$B24,"")} | J24: {=IFERROR(IFERROR(INDEX('Monthly_Cohort_&_Matrix'!$C:$N,(ROW()-17)*2+2,COLUMN()+ROW()-19),"")/$B24,"")} | ... N24: {=IFERROR(IFERROR(INDEX('Monthly_Cohort_&_Matrix'!$C:$N,(ROW()-17)*2+2,COLUMN()+ROW()-19),"")/$B24,"")}
A25: 44896 | B25: 2753173.2 | C25: {=IFERROR(IFERROR(INDEX('Monthly_Cohort_&_Matrix'!$C:$N,(ROW()-17)*2+2,COLUMN()+ROW()-19),"")/$B25,"")} -> 1 | D25: {=IFERROR(IFERROR(INDEX('Monthly_Cohort_&_Matrix'!$C:$N,(ROW()-17)*2+2,COLUMN()+ROW()-19),"")/$B25,"")} -> 1.6453966 | E25: {=IFERROR(IFERROR(INDEX('Monthly_Cohort_&_Matrix'!$C:$N,(ROW()-17)*2+2,COLUMN()+ROW()-19),"")/$B25,"")} -> 1.4008239 | F25: {=IFERROR(IFERROR(INDEX('Monthly_Cohort_&_Matrix'!$C:$N,(ROW()-17)*2+2,COLUMN()+ROW()-19),"")/$B25,"")} -> 1.3606515 | G25: {=IFERROR(IFERROR(INDEX('Monthly_Cohort_&_Matrix'!$C:$N,(ROW()-17)*2+2,COLUMN()+ROW()-19),"")/$B25,"")} | H25: {=IFERROR(IFERROR(INDEX('Monthly_Cohort_&_Matrix'!$C:$N,(ROW()-17)*2+2,COLUMN()+ROW()-19),"")/$B25,"")} | I25: {=IFERROR(IFERROR(INDEX('Monthly_Cohort_&_Matrix'!$C:$N,(ROW()-17)*2+2,COLUMN()+ROW()-19),"")/$B25,"")} | J25: {=IFERROR(IFERROR(INDEX('Monthly_Cohort_&_Matrix'!$C:$N,(ROW()-17)*2+2,COLUMN()+ROW()-19),"")/$B25,"")} | ... N25: {=IFERROR(IFERROR(INDEX('Monthly_Cohort_&_Matrix'!$C:$N,(ROW()-17)*2+2,COLUMN()+ROW()-19),"")/$B25,"")}
A26: 44927 | B26: 3024628.9 | C26: {=IFERROR(IFERROR(INDEX('Monthly_Cohort_&_Matrix'!$C:$N,(ROW()-17)*2+2,COLUMN()+ROW()-19),"")/$B26,"")} -> 1 | D26: {=IFERROR(IFERROR(INDEX('Monthly_Cohort_&_Matrix'!$C:$N,(ROW()-17)*2+2,COLUMN()+ROW()-19),"")/$B26,"")} -> 1.142497 | E26: {=IFERROR(IFERROR(INDEX('Monthly_Cohort_&_Matrix'!$C:$N,(ROW()-17)*2+2,COLUMN()+ROW()-19),"")/$B26,"")} -> 0.79460125 | F26: {=IFERROR(IFERROR(INDEX('Monthly_Cohort_&_Matrix'!$C:$N,(ROW()-17)*2+2,COLUMN()+ROW()-19),"")/$B26,"")} | G26: {=IFERROR(IFERROR(INDEX('Monthly_Cohort_&_Matrix'!$C:$N,(ROW()-17)*2+2,COLUMN()+ROW()-19),"")/$B26,"")} | H26: {=IFERROR(IFERROR(INDEX('Monthly_Cohort_&_Matrix'!$C:$N,(ROW()-17)*2+2,COLUMN()+ROW()-19),"")/$B26,"")} | I26: {=IFERROR(IFERROR(INDEX('Monthly_Cohort_&_Matrix'!$C:$N,(ROW()-17)*2+2,COLUMN()+ROW()-19),"")/$B26,"")} | J26: {=IFERROR(IFERROR(INDEX('Monthly_Cohort_&_Matrix'!$C:$N,(ROW()-17)*2+2,COLUMN()+ROW()-19),"")/$B26,"")} | ... N26: {=IFERROR(IFERROR(INDEX('Monthly_Cohort_&_Matrix'!$C:$N,(ROW()-17)*2+2,COLUMN()+ROW()-19),"")/$B26,"")}
A27: 44958 | B27: 3526821.4 | C27: {=IFERROR(IFERROR(INDEX('Monthly_Cohort_&_Matrix'!$C:$N,(ROW()-17)*2+2,COLUMN()+ROW()-19),"")/$B27,"")} -> 1 | D27: {=IFERROR(IFERROR(INDEX('Monthly_Cohort_&_Matrix'!$C:$N,(ROW()-17)*2+2,COLUMN()+ROW()-19),"")/$B27,"")} -> 1.5190736 | E27: {=IFERROR(IFERROR(INDEX('Monthly_Cohort_&_Matrix'!$C:$N,(ROW()-17)*2+2,COLUMN()+ROW()-19),"")/$B27,"")} | F27: {=IFERROR(IFERROR(INDEX('Monthly_Cohort_&_Matrix'!$C:$N,(ROW()-17)*2+2,COLUMN()+ROW()-19),"")/$B27,"")} | G27: {=IFERROR(IFERROR(INDEX('Monthly_Cohort_&_Matrix'!$C:$N,(ROW()-17)*2+2,COLUMN()+ROW()-19),"")/$B27,"")} | H27: {=IFERROR(IFERROR(INDEX('Monthly_Cohort_&_Matrix'!$C:$N,(ROW()-17)*2+2,COLUMN()+ROW()-19),"")/$B27,"")} | I27: {=IFERROR(IFERROR(INDEX('Monthly_Cohort_&_Matrix'!$C:$N,(ROW()-17)*2+2,COLUMN()+ROW()-19),"")/$B27,"")} | J27: {=IFERROR(IFERROR(INDEX('Monthly_Cohort_&_Matrix'!$C:$N,(ROW()-17)*2+2,COLUMN()+ROW()-19),"")/$B27,"")} | ... N27: {=IFERROR(IFERROR(INDEX('Monthly_Cohort_&_Matrix'!$C:$N,(ROW()-17)*2+2,COLUMN()+ROW()-19),"")/$B27,"")}
A28: 44986 | B28: 2727451.8 | C28: {=IFERROR(IFERROR(INDEX('Monthly_Cohort_&_Matrix'!$C:$N,(ROW()-17)*2+2,COLUMN()+ROW()-19),"")/$B28,"")} -> 1 | D28: {=IFERROR(IFERROR(INDEX('Monthly_Cohort_&_Matrix'!$C:$N,(ROW()-17)*2+2,COLUMN()+ROW()-19),"")/$B28,"")} | E28: {=IFERROR(IFERROR(INDEX('Monthly_Cohort_&_Matrix'!$C:$N,(ROW()-17)*2+2,COLUMN()+ROW()-19),"")/$B28,"")} | F28: {=IFERROR(IFERROR(INDEX('Monthly_Cohort_&_Matrix'!$C:$N,(ROW()-17)*2+2,COLUMN()+ROW()-19),"")/$B28,"")} | G28: {=IFERROR(IFERROR(INDEX('Monthly_Cohort_&_Matrix'!$C:$N,(ROW()-17)*2+2,COLUMN()+ROW()-19),"")/$B28,"")} | H28: {=IFERROR(IFERROR(INDEX('Monthly_Cohort_&_Matrix'!$C:$N,(ROW()-17)*2+2,COLUMN()+ROW()-19),"")/$B28,"")} | I28: {=IFERROR(IFERROR(INDEX('Monthly_Cohort_&_Matrix'!$C:$N,(ROW()-17)*2+2,COLUMN()+ROW()-19),"")/$B28,"")} | J28: {=IFERROR(IFERROR(INDEX('Monthly_Cohort_&_Matrix'!$C:$N,(ROW()-17)*2+2,COLUMN()+ROW()-19),"")/$B28,"")} | ... N28: {=IFERROR(IFERROR(INDEX('Monthly_Cohort_&_Matrix'!$C:$N,(ROW()-17)*2+2,COLUMN()+ROW()-19),"")/$B28,"")}

Sheet Users_Age_Bifurcation
A1: Txn. Month | B1: Total Users \ Age-> | C1: Same Month | D1: 1 Month Old | E1: 2 Months Old | F1: 3-5 Months Old | G1: 6-11 Months Old | I1: Txn. Month | J1: Total Users \ Age-> | K1: Same Month | L1: 1 Month Old | M1: 2 Months Old | N1: 3-5 Months Old | O1: 6-11 Months Old
A2: 44652 | B2: =SUM(C2:G2) -> 11871 | C2: 11871 | D2: 0 | E2: 0 | F2: 0 | G2: 0 | I2: 44652 | J2: =B2 -> 11871 | K2: =IFERROR(C2/$B2,0) -> 1 | L2: =IFERROR(D2/$B2,0) -> 0 | M2: =IFERROR(E2/$B2,0) -> 0 | N2: =IFERROR(F2/$B2,0) -> 0 | O2: =IFERROR(G2/$B2,0) -> 0
A3: 44682 | B3: =SUM(C3:G3) -> 17402 | C3: 15998 | D3: 1404 | E3: 0 | F3: 0 | G3: 0 | I3: 44682 | J3: =B3 -> 17402 | K3: =IFERROR(C3/$B3,0) -> 0.91931962 | L3: =IFERROR(D3/$B3,0) -> 0.080680382 | M3: =IFERROR(E3/$B3,0) -> 0 | N3: =IFERROR(F3/$B3,0) -> 0 | O3: =IFERROR(G3/$B3,0) -> 0
A4: 44713 | B4: =SUM(C4:G4) -> 21714 | C4: 19147 | D4: 1924 | E4: 643 | F4: 0 | G4: 0 | I4: 44713 | J4: =B4 -> 21714 | K4: =IFERROR(C4/$B4,0) -> 0.88178134 | L4: =IFERROR(D4/$B4,0) -> 0.088606429 | M4: =IFERROR(E4/$B4,0) -> 0.029612232 | N4: =IFERROR(F4/$B4,0) -> 0 | O4: =IFERROR(G4/$B4,0) -> 0
A5: 44743 | B5: =SUM(C5:G5) -> 22982 | C5: 19360 | D5: 2181 | E5: 916 | F5: 525 | G5: 0 | I5: 44743 | J5: =B5 -> 22982 | K5: =IFERROR(C5/$B5,0) -> 0.8423984 | L5: =IFERROR(D5/$B5,0) -> 0.094900357 | M5: =IFERROR(E5/$B5,0) -> 0.03985728 | N5: =IFERROR(F5/$B5,0) -> 0.022843965 | O5: =IFERROR(G5/$B5,0) -> 0
A6: 44774 | B6: =SUM(C6:G6) -> 21920 | C6: 18585 | D6: 1688 | E6: 693 | F6: 954 | G6: 0 | I6: 44774 | J6: =B6 -> 21920 | K6: =IFERROR(C6/$B6,0) -> 0.84785584 | L6: =IFERROR(D6/$B6,0) -> 0.077007299 | M6: =IFERROR(E6/$B6,0) -> 0.031614964 | N6: =IFERROR(F6/$B6,0) -> 0.043521898 | O6: =IFERROR(G6/$B6,0) -> 0
A7: 44805 | B7: =SUM(C7:G7) -> 17502 | C7: 13772 | D7: 1496 | E7: 831 | F7: 1403 | G7: 0 | I7: 44805 | J7: =B7 -> 17502 | K7: =IFERROR(C7/$B7,0) -> 0.7868815 | L7: =IFERROR(D7/$B7,0) -> 0.085475946 | M7: =IFERROR(E7/$B7,0) -> 0.047480288 | N7: =IFERROR(F7/$B7,0) -> 0.080162267 | O7: =IFERROR(G7/$B7,0) -> 0
A8: 44835 | B8: =SUM(C8:G8) -> 14319 | C8: 10553 | D8: 1098 | E8: 726 | F8: 1614 | G8: 328 | I8: 44835 | J8: =B8 -> 14319 | K8: =IFERROR(C8/$B8,0) -> 0.73699281 | L8: =IFERROR(D8/$B8,0) -> 0.076681332 | M8: =IFERROR(E8/$B8,0) -> 0.050701865 | N8: =IFERROR(F8/$B8,0) -> 0.11271737 | O8: =IFERROR(G8/$B8,0) -> 0.022906628
A9: 44866 | B9: =SUM(C9:G9) -> 16063 | C9: 12935 | D9: 952 | E9: 451 | F9: 1125 | G9: 600 | I9: 44866 | J9: =B9 -> 16063 | K9: =IFERROR(C9/$B9,0) -> 0.80526676 | L9: =IFERROR(D9/$B9,0) -> 0.059266638 | M9: =IFERROR(E9/$B9,0) -> 0.028076947 | N9: =IFERROR(F9/$B9,0) -> 0.07003673 | O9: =IFERROR(G9/$B9,0) -> 0.037352923
A10: 44896 | B10: =SUM(C10:G10) -> 14594 | C10: 10997 | D10: 1222 | E10: 449 | F10: 1059 | G10: 867 | I10: 44896 | J10: =B10 -> 14594 | K10: =IFERROR(C10/$B10,0) -> 0.75352885 | L10: =IFERROR(D10/$B10,0) -> 0.083733041 | M10: =IFERROR(E10/$B10,0) -> 0.030766068 | N10: =IFERROR(F10/$B10,0) -> 0.072564067 | O10: =IFERROR(G10/$B10,0) -> 0.059407976
A11: 44927 | B11: =SUM(C11:G11) -> 14870 | C11: 11697 | D11: 860 | E11: 415 | F11: 786 | G11: 1112 | I11: 44927 | J11: =B11 -> 14870 | K11: =IFERROR(C11/$B11,0) -> 0.78661735 | L11: =IFERROR(D11/$B11,0) -> 0.057834566 | M11: =IFERROR(E11/$B11,0) -> 0.027908541 | N11: =IFERROR(F11/$B11,0) -> 0.052858104 | O11: =IFERROR(G11/$B11,0) -> 0.074781439
